Workbook
Name a: #REF!
Name Ano_Sel: #REF!
Name Base_Mes: #REF!
Name Base_Safra: #REF!
Name Div_Valor: #REF!
Name Mes_Sel: #REF!
Name Moeda_Sel: #REF!
Name Rel_Recursos: #REF!
Name Tp_Desc_Mes: #REF!
Name Tp_Var: #REF!

Sheet Dimensionamento Tratos (2)
D2: DIMENSIONAMENTO DE MÁQUINAS - TRATOS CULTURAIS - OPERAÇÕES PRÓPRIAS
D5: Trator Tratos
B6: Op | C6: Fluxo | D6: Mês | E6: 45748 | F6: 45778 | G6: 45809 | H6: 45839 | I6: 45870 | J6: 45901 | K6: 45931 | L6: 45962 | M6: 45992 | N6: 46023 | O6: 46054 | P6: 46082 | Q6: Total
B7: 1031 | C7: TRATCSP | D7: =_xlfn.XLOOKUP(B7,Apoio!A:A,Apoio!B:B) -> 1ª Aplicação De Herbicida | E7: =SUMIFS(Qtde_Oper_Plantio_Tratos!P:P,Qtde_Oper_Plantio_Tratos!$F:$F,'Dimensionamento Tratos (2)'!$B7,Qtde_Oper_Plantio_Tratos!$I:$I,'Dimensionamento Tratos (2)'!$C7) -> 1329.522 | F7: =SUMIFS(Qtde_Oper_Plantio_Tratos!Q:Q,Qtde_Oper_Plantio_Tratos!$F:$F,'Dimensionamento Tratos (2)'!$B7,Qtde_Oper_Plantio_Tratos!$I:$I,'Dimensionamento Tratos (2)'!$C7) -> 2090.75 | G7: =SUMIFS(Qtde_Oper_Plantio_Tratos!R:R,Qtde_Oper_Plantio_Tratos!$F:$F,'Dimensionamento Tratos (2)'!$B7,Qtde_Oper_Plantio_Tratos!$I:$I,'Dimensionamento Tratos (2)'!$C7) -> 2335.49 | H7: =SUMIFS(Qtde_Oper_Plantio_Tratos!S:S,Qtde_Oper_Plantio_Tratos!$F:$F,'Dimensionamento Tratos (2)'!$B7,Qtde_Oper_Plantio_Tratos!$I:$I,'Dimensionamento Tratos (2)'!$C7) -> 1476.67 | I7: =SUMIFS(Qtde_Oper_Plantio_Tratos!T:T,Qtde_Oper_Plantio_Tratos!$F:$F,'Dimensionamento Tratos (2)'!$B7,Qtde_Oper_Plantio_Tratos!$I:$I,'Dimensionamento Tratos (2)'!$C7) -> 1496.14 | J7: =SUMIFS(Qtde_Oper_Plantio_Tratos!U:U,Qtde_Oper_Plantio_Tratos!$F:$F,'Dimensionamento Tratos (2)'!$B7,Qtde_Oper_Plantio_Tratos!$I:$I,'Dimensionamento Tratos (2)'!$C7) -> 1659.82 | K7: =SUMIFS(Qtde_Oper_Plantio_Tratos!V:V,Qtde_Oper_Plantio_Tratos!$F:$F,'Dimensionamento Tratos (2)'!$B7,Qtde_Oper_Plantio_Tratos!$I:$I,'Dimensionamento Tratos (2)'!$C7) -> 1868.84 | L7: =SUMIFS(Qtde_Oper_Plantio_Tratos!W:W,Qtde_Oper_Plantio_Tratos!$F:$F,'Dimensionamento Tratos (2)'!$B7,Qtde_Oper_Plantio_Tratos!$I:$I,'Dimensionamento Tratos (2)'!$C7) -> 1005.77 | M7: =SUMIFS(Qtde_Oper_Plantio_Tratos!X:X,Qtde_Oper_Plantio_Tratos!$F:$F,'Dimensionamento Tratos (2)'!$B7,Qtde_Oper_Plantio_Tratos!$I:$I,'Dimensionamento Tratos (2)'!$C7) -> 0 | N7: =SUMIFS(Qtde_Oper_Plantio_Tratos!Y:Y,Qtde_Oper_Plantio_Tratos!$F:$F,'Dimensionamento Tratos (2)'!$B7,Qtde_Oper_Plantio_Tratos!$I:$I,'Dimensionamento Tratos (2)'!$C7) -> 0 | O7: =SUMIFS(Qtde_Oper_Plantio_Tratos!Z:Z,Qtde_Oper_Plantio_Tratos!$F:$F,'Dimensionamento Tratos (2)'!$B7,Qtde_Oper_Plantio_Tratos!$I:$I,'Dimensionamento Tratos (2)'!$C7) -> 100 | P7: =SUMIFS(Qtde_Oper_Plantio_Tratos!AA:AA,Qtde_Oper_Plantio_Tratos!$F:$F,'Dimensionamento Tratos (2)'!$B7,Qtde_Oper_Plantio_Tratos!$I:$I,'Dimensionamento Tratos (2)'!$C7) -> 100 | Q7: =SUM(E7:P7) -> 13463.002
C8: Proprio | D8: Trator_Herbicida | E8: =IF($C8="Proprio",IFERROR(E7/(_xlfn.XLOOKUP(E$6,$E$68:$Q$68,$E$69:$Q$69)*_xlfn.XLOOKUP($B7,$C$52:$C$64,$E$52:$E$64)),0),0) -> 0.71551917 | F8: =IF($C8="Proprio",IFERROR(F7/(_xlfn.XLOOKUP(F$6,$E$68:$Q$68,$E$69:$Q$69)*_xlfn.XLOOKUP($B7,$C$52:$C$64,$E$52:$E$64)),0),0) -> 1.0221495 | G8: =IF($C8="Proprio",IFERROR(G7/(_xlfn.XLOOKUP(G$6,$E$68:$Q$68,$E$69:$Q$69)*_xlfn.XLOOKUP($B7,$C$52:$C$64,$E$52:$E$64)),0),0) -> 1.1070366 | H8: =IF($C8="Proprio",IFERROR(H7/(_xlfn.XLOOKUP(H$6,$E$68:$Q$68,$E$69:$Q$69)*_xlfn.XLOOKUP($B7,$C$52:$C$64,$E$52:$E$64)),0),0) -> 0.64087568 | I8: =IF($C8="Proprio",IFERROR(I7/(_xlfn.XLOOKUP(I$6,$E$68:$Q$68,$E$69:$Q$69)*_xlfn.XLOOKUP($B7,$C$52:$C$64,$E$52:$E$64)),0),0) -> 0.65945805 | J8: =IF($C8="Proprio",IFERROR(J7/(_xlfn.XLOOKUP(J$6,$E$68:$Q$68,$E$69:$Q$69)*_xlfn.XLOOKUP($B7,$C$52:$C$64,$E$52:$E$64)),0),0) -> 0.80731796 | K8: =IF($C8="Proprio",IFERROR(K7/(_xlfn.XLOOKUP(K$6,$E$68:$Q$68,$E$69:$Q$69)*_xlfn.XLOOKUP($B7,$C$52:$C$64,$E$52:$E$64)),0),0) -> 1.0183337 | L8: =IF($C8="Proprio",IFERROR(L7/(_xlfn.XLOOKUP(L$6,$E$68:$Q$68,$E$69:$Q$69)*_xlfn.XLOOKUP($B7,$C$52:$C$64,$E$52:$E$64)),0),0) -> 0.61268679 | ... P8: =IF($C8="Proprio",IFERROR(P7/(_xlfn.XLOOKUP(P$6,$E$68:$Q$68,$E$69:$Q$69)*_xlfn.XLOOKUP($B7,$C$52:$C$64,$E$52:$E$64)),0),0) -> 0.070323488 | Q8: =IFERROR(Q7/(_xlfn.XLOOKUP(Q$6,$E$68:$Q$68,$E$69:$Q$69)*_xlfn.XLOOKUP($B7,$C$52:$C$64,$E$52:$E$64)),0) -> 0.66404391
B9: 1073 | C9: TRATCSP | D9: =_xlfn.XLOOKUP(B9,Apoio!A:A,Apoio!B:B) -> Apl Inseticida Em Profundidade | E9: =SUMIFS(Qtde_Oper_Plantio_Tratos!P:P,Qtde_Oper_Plantio_Tratos!$F:$F,'Dimensionamento Tratos (2)'!$B9,Qtde_Oper_Plantio_Tratos!$I:$I,'Dimensionamento Tratos (2)'!$C9) -> 1500 | F9: =SUMIFS(Qtde_Oper_Plantio_Tratos!Q:Q,Qtde_Oper_Plantio_Tratos!$F:$F,'Dimensionamento Tratos (2)'!$B9,Qtde_Oper_Plantio_Tratos!$I:$I,'Dimensionamento Tratos (2)'!$C9) -> 1800 | G9: =SUMIFS(Qtde_Oper_Plantio_Tratos!R:R,Qtde_Oper_Plantio_Tratos!$F:$F,'Dimensionamento Tratos (2)'!$B9,Qtde_Oper_Plantio_Tratos!$I:$I,'Dimensionamento Tratos (2)'!$C9) -> 1800 | H9: =SUMIFS(Qtde_Oper_Plantio_Tratos!S:S,Qtde_Oper_Plantio_Tratos!$F:$F,'Dimensionamento Tratos (2)'!$B9,Qtde_Oper_Plantio_Tratos!$I:$I,'Dimensionamento Tratos (2)'!$C9) -> 1932.63 | I9: =SUMIFS(Qtde_Oper_Plantio_Tratos!T:T,Qtde_Oper_Plantio_Tratos!$F:$F,'Dimensionamento Tratos (2)'!$B9,Qtde_Oper_Plantio_Tratos!$I:$I,'Dimensionamento Tratos (2)'!$C9) -> 1496.14 | J9: =SUMIFS(Qtde_Oper_Plantio_Tratos!U:U,Qtde_Oper_Plantio_Tratos!$F:$F,'Dimensionamento Tratos (2)'!$B9,Qtde_Oper_Plantio_Tratos!$I:$I,'Dimensionamento Tratos (2)'!$C9) -> 1659.82 | K9: =SUMIFS(Qtde_Oper_Plantio_Tratos!V:V,Qtde_Oper_Plantio_Tratos!$F:$F,'Dimensionamento Tratos (2)'!$B9,Qtde_Oper_Plantio_Tratos!$I:$I,'Dimensionamento Tratos (2)'!$C9) -> 1868.64 | L9: =SUMIFS(Qtde_Oper_Plantio_Tratos!W:W,Qtde_Oper_Plantio_Tratos!$F:$F,'Dimensionamento Tratos (2)'!$B9,Qtde_Oper_Plantio_Tratos!$I:$I,'Dimensionamento Tratos (2)'!$C9) -> 1005.77 | M9: =SUMIFS(Qtde_Oper_Plantio_Tratos!X:X,Qtde_Oper_Plantio_Tratos!$F:$F,'Dimensionamento Tratos (2)'!$B9,Qtde_Oper_Plantio_Tratos!$I:$I,'Dimensionamento Tratos (2)'!$C9) -> 0 | N9: =SUMIFS(Qtde_Oper_Plantio_Tratos!Y:Y,Qtde_Oper_Plantio_Tratos!$F:$F,'Dimensionamento Tratos (2)'!$B9,Qtde_Oper_Plantio_Tratos!$I:$I,'Dimensionamento Tratos (2)'!$C9) -> 0 | O9: =SUMIFS(Qtde_Oper_Plantio_Tratos!Z:Z,Qtde_Oper_Plantio_Tratos!$F:$F,'Dimensionamento Tratos (2)'!$B9,Qtde_Oper_Plantio_Tratos!$I:$I,'Dimensionamento Tratos (2)'!$C9) -> 100 | P9: =SUMIFS(Qtde_Oper_Plantio_Tratos!AA:AA,Qtde_Oper_Plantio_Tratos!$F:$F,'Dimensionamento Tratos (2)'!$B9,Qtde_Oper_Plantio_Tratos!$I:$I,'Dimensionamento Tratos (2)'!$C9) -> 100 | Q9: =SUMIFS(Qtde_Oper_Plantio_Tratos!AB:AB,Qtde_Oper_Plantio_Tratos!$F:$F,'Dimensionamento Tratos (2)'!$B9,Qtde_Oper_Plantio_Tratos!$I:$I,'Dimensionamento Tratos (2)'!$C9) -> 13263
C10: Proprio | D10: Trator_Apl Inseticida Em Profundidade | E10: =IF($C10="Proprio",IFERROR(E9/(_xlfn.XLOOKUP(E$6,$E$68:$Q$68,$E$69:$Q$69)*_xlfn.XLOOKUP($B9,$C$52:$C$64,$E$52:$E$64)),0),0) -> 10.541168 | F10: =IF($C10="Proprio",IFERROR(F9/(_xlfn.XLOOKUP(F$6,$E$68:$Q$68,$E$69:$Q$69)*_xlfn.XLOOKUP($B9,$C$52:$C$64,$E$52:$E$64)),0),0) -> 11.490966 | G10: =IF($C10="Proprio",IFERROR(G9/(_xlfn.XLOOKUP(G$6,$E$68:$Q$68,$E$69:$Q$69)*_xlfn.XLOOKUP($B9,$C$52:$C$64,$E$52:$E$64)),0),0) -> 11.141103 | H10: =IF($C10="Proprio",IFERROR(H9/(_xlfn.XLOOKUP(H$6,$E$68:$Q$68,$E$69:$Q$69)*_xlfn.XLOOKUP($B9,$C$52:$C$64,$E$52:$E$64)),0),0) -> 10.952437 | I10: =IF($C10="Proprio",IFERROR(I9/(_xlfn.XLOOKUP(I$6,$E$68:$Q$68,$E$69:$Q$69)*_xlfn.XLOOKUP($B9,$C$52:$C$64,$E$52:$E$64)),0),0) -> 8.6111051 | J10: =IF($C10="Proprio",IFERROR(J9/(_xlfn.XLOOKUP(J$6,$E$68:$Q$68,$E$69:$Q$69)*_xlfn.XLOOKUP($B9,$C$52:$C$64,$E$52:$E$64)),0),0) -> 10.541838 | K10: =IF($C10="Proprio",IFERROR(K9/(_xlfn.XLOOKUP(K$6,$E$68:$Q$68,$E$69:$Q$69)*_xlfn.XLOOKUP($B9,$C$52:$C$64,$E$52:$E$64)),0),0) -> 13.295828 | L10: =IF($C10="Proprio",IFERROR(L9/(_xlfn.XLOOKUP(L$6,$E$68:$Q$68,$E$69:$Q$69)*_xlfn.XLOOKUP($B9,$C$52:$C$64,$E$52:$E$64)),0),0) -> 8.0003729 | ... P10: =IF($C10="Proprio",IFERROR(P9/(_xlfn.XLOOKUP(P$6,$E$68:$Q$68,$E$69:$Q$69)*_xlfn.XLOOKUP($B9,$C$52:$C$64,$E$52:$E$64)),0),0) -> 0.91827365 | Q10: =IFERROR(Q9/(_xlfn.XLOOKUP(Q$6,$E$68:$Q$68,$E$69:$Q$69)*_xlfn.XLOOKUP($B9,$C$52:$C$64,$E$52:$E$64)),0) -> 8.5421732
B11: 1033 | C11: TRATCSP | D11: =_xlfn.XLOOKUP(B11,Apoio!A:A,Apoio!B:B) -> Aplicação De Torta De Filtro | E11: =SUMIFS(Qtde_Oper_Plantio_Tratos!P:P,Qtde_Oper_Plantio_Tratos!$F:$F,'Dimensionamento Tratos (2)'!$B11,Qtde_Oper_Plantio_Tratos!$I:$I,'Dimensionamento Tratos (2)'!$C11) -> 322.16 | F11: =SUMIFS(Qtde_Oper_Plantio_Tratos!Q:Q,Qtde_Oper_Plantio_Tratos!$F:$F,'Dimensionamento Tratos (2)'!$B11,Qtde_Oper_Plantio_Tratos!$I:$I,'Dimensionamento Tratos (2)'!$C11) -> 543.24 | G11: =SUMIFS(Qtde_Oper_Plantio_Tratos!R:R,Qtde_Oper_Plantio_Tratos!$F:$F,'Dimensionamento Tratos (2)'!$B11,Qtde_Oper_Plantio_Tratos!$I:$I,'Dimensionamento Tratos (2)'!$C11) -> 291.06 | H11: =SUMIFS(Qtde_Oper_Plantio_Tratos!S:S,Qtde_Oper_Plantio_Tratos!$F:$F,'Dimensionamento Tratos (2)'!$B11,Qtde_Oper_Plantio_Tratos!$I:$I,'Dimensionamento Tratos (2)'!$C11) -> 120.53 | I11: =SUMIFS(Qtde_Oper_Plantio_Tratos!T:T,Qtde_Oper_Plantio_Tratos!$F:$F,'Dimensionamento Tratos (2)'!$B11,Qtde_Oper_Plantio_Tratos!$I:$I,'Dimensionamento Tratos (2)'!$C11) -> 106.19 | J11: =SUMIFS(Qtde_Oper_Plantio_Tratos!U:U,Qtde_Oper_Plantio_Tratos!$F:$F,'Dimensionamento Tratos (2)'!$B11,Qtde_Oper_Plantio_Tratos!$I:$I,'Dimensionamento Tratos (2)'!$C11) -> 262.37 | K11: =SUMIFS(Qtde_Oper_Plantio_Tratos!V:V,Qtde_Oper_Plantio_Tratos!$F:$F,'Dimensionamento Tratos (2)'!$B11,Qtde_Oper_Plantio_Tratos!$I:$I,'Dimensionamento Tratos (2)'!$C11) -> 593.81 | L11: =SUMIFS(Qtde_Oper_Plantio_Tratos!W:W,Qtde_Oper_Plantio_Tratos!$F:$F,'Dimensionamento Tratos (2)'!$B11,Qtde_Oper_Plantio_Tratos!$I:$I,'Dimensionamento Tratos (2)'!$C11) -> 337.88 | M11: =SUMIFS(Qtde_Oper_Plantio_Tratos!X:X,Qtde_Oper_Plantio_Tratos!$F:$F,'Dimensionamento Tratos (2)'!$B11,Qtde_Oper_Plantio_Tratos!$I:$I,'Dimensionamento Tratos (2)'!$C11) -> 0 | N11: =SUMIFS(Qtde_Oper_Plantio_Tratos!Y:Y,Qtde_Oper_Plantio_Tratos!$F:$F,'Dimensionamento Tratos (2)'!$B11,Qtde_Oper_Plantio_Tratos!$I:$I,'Dimensionamento Tratos (2)'!$C11) -> 0 | O11: =SUMIFS(Qtde_Oper_Plantio_Tratos!Z:Z,Qtde_Oper_Plantio_Tratos!$F:$F,'Dimensionamento Tratos (2)'!$B11,Qtde_Oper_Plantio_Tratos!$I:$I,'Dimensionamento Tratos (2)'!$C11) -> 0 | P11: =SUMIFS(Qtde_Oper_Plantio_Tratos!AA:AA,Qtde_Oper_Plantio_Tratos!$F:$F,'Dimensionamento Tratos (2)'!$B11,Qtde_Oper_Plantio_Tratos!$I:$I,'Dimensionamento Tratos (2)'!$C11) -> 0 | Q11: =SUM(E11:P11) -> 2577.24
C12: Proprio | D12: Trator_Torta | E12: =IF($C12="Proprio",IFERROR(E11/(_xlfn.XLOOKUP(E$6,$E$68:$Q$68,$E$69:$Q$69)*_xlfn.XLOOKUP($B11,$C$52:$C$64,$E$52:$E$64)),0),0) -> 4.6066037 | F12: =IF($C12="Proprio",IFERROR(F11/(_xlfn.XLOOKUP(F$6,$E$68:$Q$68,$E$69:$Q$69)*_xlfn.XLOOKUP($B11,$C$52:$C$64,$E$52:$E$64)),0),0) -> 7.0564711 | G12: =IF($C12="Proprio",IFERROR(G11/(_xlfn.XLOOKUP(G$6,$E$68:$Q$68,$E$69:$Q$69)*_xlfn.XLOOKUP($B11,$C$52:$C$64,$E$52:$E$64)),0),0) -> 3.6656414 | H12: =IF($C12="Proprio",IFERROR(H11/(_xlfn.XLOOKUP(H$6,$E$68:$Q$68,$E$69:$Q$69)*_xlfn.XLOOKUP($B11,$C$52:$C$64,$E$52:$E$64)),0),0) -> 1.3898534 | I12: =IF($C12="Proprio",IFERROR(I11/(_xlfn.XLOOKUP(I$6,$E$68:$Q$68,$E$69:$Q$69)*_xlfn.XLOOKUP($B11,$C$52:$C$64,$E$52:$E$64)),0),0) -> 1.2436038 | J12: =IF($C12="Proprio",IFERROR(J11/(_xlfn.XLOOKUP(J$6,$E$68:$Q$68,$E$69:$Q$69)*_xlfn.XLOOKUP($B11,$C$52:$C$64,$E$52:$E$64)),0),0) -> 3.3906369 | K12: =IF($C12="Proprio",IFERROR(K11/(_xlfn.XLOOKUP(K$6,$E$68:$Q$68,$E$69:$Q$69)*_xlfn.XLOOKUP($B11,$C$52:$C$64,$E$52:$E$64)),0),0) -> 8.5970413 | L12: =IF($C12="Proprio",IFERROR(L11/(_xlfn.XLOOKUP(L$6,$E$68:$Q$68,$E$69:$Q$69)*_xlfn.XLOOKUP($B11,$C$52:$C$64,$E$52:$E$64)),0),0) -> 5.4687216 | ... P12: =IF($C12="Proprio",IFERROR(P11/(_xlfn.XLOOKUP(P$6,$E$68:$Q$68,$E$69:$Q$69)*_xlfn.XLOOKUP($B11,$C$52:$C$64,$E$52:$E$64)),0),0) -> 0 | Q12: =IFERROR(Q11/(_xlfn.XLOOKUP(Q$6,$E$68:$Q$68,$E$69:$Q$69)*_xlfn.XLOOKUP($B11,$C$52:$C$64,$E$52:$E$64)),0) -> 3.3774835
B13: 1022 | C13: TRATCSP | D13: =_xlfn.XLOOKUP(B13,Apoio!A:A,Apoio!B:B) -> Cultivo | E13: =SUMIFS(Qtde_Oper_Plantio_Tratos!P:P,Qtde_Oper_Plantio_Tratos!$F:$F,'Dimensionamento Tratos (2)'!$B13,Qtde_Oper_Plantio_Tratos!$I:$I,'Dimensionamento Tratos (2)'!$C13) -> 57.05 | F13: =SUMIFS(Qtde_Oper_Plantio_Tratos!Q:Q,Qtde_Oper_Plantio_Tratos!$F:$F,'Dimensionamento Tratos (2)'!$B13,Qtde_Oper_Plantio_Tratos!$I:$I,'Dimensionamento Tratos (2)'!$C13) -> 70.15 | G13: =SUMIFS(Qtde_Oper_Plantio_Tratos!R:R,Qtde_Oper_Plantio_Tratos!$F:$F,'Dimensionamento Tratos (2)'!$B13,Qtde_Oper_Plantio_Tratos!$I:$I,'Dimensionamento Tratos (2)'!$C13) -> 0 | H13: =SUMIFS(Qtde_Oper_Plantio_Tratos!S:S,Qtde_Oper_Plantio_Tratos!$F:$F,'Dimensionamento Tratos (2)'!$B13,Qtde_Oper_Plantio_Tratos!$I:$I,'Dimensionamento Tratos (2)'!$C13) -> 103.64 | I13: =SUMIFS(Qtde_Oper_Plantio_Tratos!T:T,Qtde_Oper_Plantio_Tratos!$F:$F,'Dimensionamento Tratos (2)'!$B13,Qtde_Oper_Plantio_Tratos!$I:$I,'Dimensionamento Tratos (2)'!$C13) -> 57 | J13: =SUMIFS(Qtde_Oper_Plantio_Tratos!U:U,Qtde_Oper_Plantio_Tratos!$F:$F,'Dimensionamento Tratos (2)'!$B13,Qtde_Oper_Plantio_Tratos!$I:$I,'Dimensionamento Tratos (2)'!$C13) -> 16.44 | K13: =SUMIFS(Qtde_Oper_Plantio_Tratos!V:V,Qtde_Oper_Plantio_Tratos!$F:$F,'Dimensionamento Tratos (2)'!$B13,Qtde_Oper_Plantio_Tratos!$I:$I,'Dimensionamento Tratos (2)'!$C13) -> 0.2 | L13: =SUMIFS(Qtde_Oper_Plantio_Tratos!W:W,Qtde_Oper_Plantio_Tratos!$F:$F,'Dimensionamento Tratos (2)'!$B13,Qtde_Oper_Plantio_Tratos!$I:$I,'Dimensionamento Tratos (2)'!$C13) -> 368.65 | M13: =SUMIFS(Qtde_Oper_Plantio_Tratos!X:X,Qtde_Oper_Plantio_Tratos!$F:$F,'Dimensionamento Tratos (2)'!$B13,Qtde_Oper_Plantio_Tratos!$I:$I,'Dimensionamento Tratos (2)'!$C13) -> 0 | N13: =SUMIFS(Qtde_Oper_Plantio_Tratos!Y:Y,Qtde_Oper_Plantio_Tratos!$F:$F,'Dimensionamento Tratos (2)'!$B13,Qtde_Oper_Plantio_Tratos!$I:$I,'Dimensionamento Tratos (2)'!$C13) -> 0 | O13: =SUMIFS(Qtde_Oper_Plantio_Tratos!Z:Z,Qtde_Oper_Plantio_Tratos!$F:$F,'Dimensionamento Tratos (2)'!$B13,Qtde_Oper_Plantio_Tratos!$I:$I,'Dimensionamento Tratos (2)'!$C13) -> 100 | P13: =SUMIFS(Qtde_Oper_Plantio_Tratos!AA:AA,Qtde_Oper_Plantio_Tratos!$F:$F,'Dimensionamento Tratos (2)'!$B13,Qtde_Oper_Plantio_Tratos!$I:$I,'Dimensionamento Tratos (2)'!$C13) -> 100 | Q13: =SUMIFS(Qtde_Oper_Plantio_Tratos!AB:AB,Qtde_Oper_Plantio_Tratos!$F:$F,'Dimensionamento Tratos (2)'!$B13,Qtde_Oper_Plantio_Tratos!$I:$I,'Dimensionamento Tratos (2)'!$C13) -> 873.13
C14: Proprio | D14: Trator_Cultivo | E14: =IF($C14="Proprio",IFERROR(E13/(_xlfn.XLOOKUP(E$6,$E$68:$Q$68,$E$69:$Q$69)*_xlfn.XLOOKUP($B13,$C$52:$C$64,$E$52:$E$64)),0),0) -> 0.40091574 | F14: =IF($C14="Proprio",IFERROR(F13/(_xlfn.XLOOKUP(F$6,$E$68:$Q$68,$E$69:$Q$69)*_xlfn.XLOOKUP($B13,$C$52:$C$64,$E$52:$E$64)),0),0) -> 0.4478285 | G14: =IF($C14="Proprio",IFERROR(G13/(_xlfn.XLOOKUP(G$6,$E$68:$Q$68,$E$69:$Q$69)*_xlfn.XLOOKUP($B13,$C$52:$C$64,$E$52:$E$64)),0),0) -> 0 | H14: =IF($C14="Proprio",IFERROR(H13/(_xlfn.XLOOKUP(H$6,$E$68:$Q$68,$E$69:$Q$69)*_xlfn.XLOOKUP($B13,$C$52:$C$64,$E$52:$E$64)),0),0) -> 0.58733984 | I14: =IF($C14="Proprio",IFERROR(I13/(_xlfn.XLOOKUP(I$6,$E$68:$Q$68,$E$69:$Q$69)*_xlfn.XLOOKUP($B13,$C$52:$C$64,$E$52:$E$64)),0),0) -> 0.32806622 | J14: =IF($C14="Proprio",IFERROR(J13/(_xlfn.XLOOKUP(J$6,$E$68:$Q$68,$E$69:$Q$69)*_xlfn.XLOOKUP($B13,$C$52:$C$64,$E$52:$E$64)),0),0) -> 0.10441362 | K14: =IF($C14="Proprio",IFERROR(K13/(_xlfn.XLOOKUP(K$6,$E$68:$Q$68,$E$69:$Q$69)*_xlfn.XLOOKUP($B13,$C$52:$C$64,$E$52:$E$64)),0),0) -> 0.0014230486 | L14: =IF($C14="Proprio",IFERROR(L13/(_xlfn.XLOOKUP(L$6,$E$68:$Q$68,$E$69:$Q$69)*_xlfn.XLOOKUP($B13,$C$52:$C$64,$E$52:$E$64)),0),0) -> 2.9324174 | ... P14: =IF($C14="Proprio",IFERROR(P13/(_xlfn.XLOOKUP(P$6,$E$68:$Q$68,$E$69:$Q$69)*_xlfn.XLOOKUP($B13,$C$52:$C$64,$E$52:$E$64)),0),0) -> 0.91827365 | Q14: =IFERROR(Q13/(_xlfn.XLOOKUP(Q$6,$E$68:$Q$68,$E$69:$Q$69)*_xlfn.XLOOKUP($B13,$C$52:$C$64,$E$52:$E$64)),0) -> 0.56234846
B15: 1022 | C15: TRATCSF | D15: =_xlfn.XLOOKUP(B15,Apoio!A:A,Apoio!B:B) -> Cultivo | E15: =SUMIFS(Qtde_Oper_Plantio_Tratos!P:P,Qtde_Oper_Plantio_Tratos!$F:$F,'Dimensionamento Tratos (2)'!$B15,Qtde_Oper_Plantio_Tratos!$I:$I,'Dimensionamento Tratos (2)'!$C15) -> 0 | F15: =SUMIFS(Qtde_Oper_Plantio_Tratos!Q:Q,Qtde_Oper_Plantio_Tratos!$F:$F,'Dimensionamento Tratos (2)'!$B15,Qtde_Oper_Plantio_Tratos!$I:$I,'Dimensionamento Tratos (2)'!$C15) -> 0 | G15: =SUMIFS(Qtde_Oper_Plantio_Tratos!R:R,Qtde_Oper_Plantio_Tratos!$F:$F,'Dimensionamento Tratos (2)'!$B15,Qtde_Oper_Plantio_Tratos!$I:$I,'Dimensionamento Tratos (2)'!$C15) -> 100 | H15: =SUMIFS(Qtde_Oper_Plantio_Tratos!S:S,Qtde_Oper_Plantio_Tratos!$F:$F,'Dimensionamento Tratos (2)'!$B15,Qtde_Oper_Plantio_Tratos!$I:$I,'Dimensionamento Tratos (2)'!$C15) -> 0 | I15: =SUMIFS(Qtde_Oper_Plantio_Tratos!T:T,Qtde_Oper_Plantio_Tratos!$F:$F,'Dimensionamento Tratos (2)'!$B15,Qtde_Oper_Plantio_Tratos!$I:$I,'Dimensionamento Tratos (2)'!$C15) -> 100 | J15: =SUMIFS(Qtde_Oper_Plantio_Tratos!U:U,Qtde_Oper_Plantio_Tratos!$F:$F,'Dimensionamento Tratos (2)'!$B15,Qtde_Oper_Plantio_Tratos!$I:$I,'Dimensionamento Tratos (2)'!$C15) -> 100 | K15: =SUMIFS(Qtde_Oper_Plantio_Tratos!V:V,Qtde_Oper_Plantio_Tratos!$F:$F,'Dimensionamento Tratos (2)'!$B15,Qtde_Oper_Plantio_Tratos!$I:$I,'Dimensionamento Tratos (2)'!$C15) -> 100 | L15: =SUMIFS(Qtde_Oper_Plantio_Tratos!W:W,Qtde_Oper_Plantio_Tratos!$F:$F,'Dimensionamento Tratos (2)'!$B15,Qtde_Oper_Plantio_Tratos!$I:$I,'Dimensionamento Tratos (2)'!$C15) -> 0 | M15: =SUMIFS(Qtde_Oper_Plantio_Tratos!X:X,Qtde_Oper_Plantio_Tratos!$F:$F,'Dimensionamento Tratos (2)'!$B15,Qtde_Oper_Plantio_Tratos!$I:$I,'Dimensionamento Tratos (2)'!$C15) -> 0 | N15: =SUMIFS(Qtde_Oper_Plantio_Tratos!Y:Y,Qtde_Oper_Plantio_Tratos!$F:$F,'Dimensionamento Tratos (2)'!$B15,Qtde_Oper_Plantio_Tratos!$I:$I,'Dimensionamento Tratos (2)'!$C15) -> 0 | O15: =SUMIFS(Qtde_Oper_Plantio_Tratos!Z:Z,Qtde_Oper_Plantio_Tratos!$F:$F,'Dimensionamento Tratos (2)'!$B15,Qtde_Oper_Plantio_Tratos!$I:$I,'Dimensionamento Tratos (2)'!$C15) -> 0 | P15: =SUMIFS(Qtde_Oper_Plantio_Tratos!AA:AA,Qtde_Oper_Plantio_Tratos!$F:$F,'Dimensionamento Tratos (2)'!$B15,Qtde_Oper_Plantio_Tratos!$I:$I,'Dimensionamento Tratos (2)'!$C15) -> 0 | Q15: =SUM(E15:P15) -> 400
C16: Proprio | D16: Trator_Correção Solo | E16: =IF($C16="Proprio",IFERROR(E15/(_xlfn.XLOOKUP(E$6,$E$68:$Q$68,$E$69:$Q$69)*_xlfn.XLOOKUP($B15,$C$52:$C$64,$E$52:$E$64)),0),0) -> 0 | F16: =IF($C16="Proprio",IFERROR(F15/(_xlfn.XLOOKUP(F$6,$E$68:$Q$68,$E$69:$Q$69)*_xlfn.XLOOKUP($B15,$C$52:$C$64,$E$52:$E$64)),0),0) -> 0 | G16: =IF($C16="Proprio",IFERROR(G15/(_xlfn.XLOOKUP(G$6,$E$68:$Q$68,$E$69:$Q$69)*_xlfn.XLOOKUP($B15,$C$52:$C$64,$E$52:$E$64)),0),0) -> 0.61895015 | H16: =IF($C16="Proprio",IFERROR(H15/(_xlfn.XLOOKUP(H$6,$E$68:$Q$68,$E$69:$Q$69)*_xlfn.XLOOKUP($B15,$C$52:$C$64,$E$52:$E$64)),0),0) -> 0 | I16: =IF($C16="Proprio",IFERROR(I15/(_xlfn.XLOOKUP(I$6,$E$68:$Q$68,$E$69:$Q$69)*_xlfn.XLOOKUP($B15,$C$52:$C$64,$E$52:$E$64)),0),0) -> 0.57555477 | J16: =IF($C16="Proprio",IFERROR(J15/(_xlfn.XLOOKUP(J$6,$E$68:$Q$68,$E$69:$Q$69)*_xlfn.XLOOKUP($B15,$C$52:$C$64,$E$52:$E$64)),0),0) -> 0.63511934 | K16: =IF($C16="Proprio",IFERROR(K15/(_xlfn.XLOOKUP(K$6,$E$68:$Q$68,$E$69:$Q$69)*_xlfn.XLOOKUP($B15,$C$52:$C$64,$E$52:$E$64)),0),0) -> 0.71152429 | L16: =IF($C16="Proprio",IFERROR(L15/(_xlfn.XLOOKUP(L$6,$E$68:$Q$68,$E$69:$Q$69)*_xlfn.XLOOKUP($B15,$C$52:$C$64,$E$52:$E$64)),0),0) -> 0 | ... P16: =IF($C16="Proprio",IFERROR(P15/(_xlfn.XLOOKUP(P$6,$E$68:$Q$68,$E$69:$Q$69)*_xlfn.XLOOKUP($B15,$C$52:$C$64,$E$52:$E$64)),0),0) -> 0 | Q16: =IFERROR(Q15/(_xlfn.XLOOKUP(Q$6,$E$68:$Q$68,$E$69:$Q$69)*_xlfn.XLOOKUP($B15,$C$52:$C$64,$E$52:$E$64)),0) -> 0.25762416
B17: 1078 | C17: TRATCSP | D17: =_xlfn.XLOOKUP(B17,Apoio!A:A,Apoio!B:B) -> 2ª Aplicação De Herbicida | E17: =SUMIFS(Qtde_Oper_Plantio_Tratos!P:P,Qtde_Oper_Plantio_Tratos!$F:$F,'Dimensionamento Tratos (2)'!$B17,Qtde_Oper_Plantio_Tratos!$I:$I,'Dimensionamento Tratos (2)'!$C17) -> 0 | F17: =SUMIFS(Qtde_Oper_Plantio_Tratos!Q:Q,Qtde_Oper_Plantio_Tratos!$F:$F,'Dimensionamento Tratos (2)'!$B17,Qtde_Oper_Plantio_Tratos!$I:$I,'Dimensionamento Tratos (2)'!$C17) -> 0 | G17: =SUMIFS(Qtde_Oper_Plantio_Tratos!R:R,Qtde_Oper_Plantio_Tratos!$F:$F,'Dimensionamento Tratos (2)'!$B17,Qtde_Oper_Plantio_Tratos!$I:$I,'Dimensionamento Tratos (2)'!$C17) -> 554.638 | H17: =SUMIFS(Qtde_Oper_Plantio_Tratos!S:S,Qtde_Oper_Plantio_Tratos!$F:$F,'Dimensionamento Tratos (2)'!$B17,Qtde_Oper_Plantio_Tratos!$I:$I,'Dimensionamento Tratos (2)'!$C17) -> 0 | I17: =SUMIFS(Qtde_Oper_Plantio_Tratos!T:T,Qtde_Oper_Plantio_Tratos!$F:$F,'Dimensionamento Tratos (2)'!$B17,Qtde_Oper_Plantio_Tratos!$I:$I,'Dimensionamento Tratos (2)'!$C17) -> 523.649 | J17: =SUMIFS(Qtde_Oper_Plantio_Tratos!U:U,Qtde_Oper_Plantio_Tratos!$F:$F,'Dimensionamento Tratos (2)'!$B17,Qtde_Oper_Plantio_Tratos!$I:$I,'Dimensionamento Tratos (2)'!$C17) -> 580.937 | K17: =SUMIFS(Qtde_Oper_Plantio_Tratos!V:V,Qtde_Oper_Plantio_Tratos!$F:$F,'Dimensionamento Tratos (2)'!$B17,Qtde_Oper_Plantio_Tratos!$I:$I,'Dimensionamento Tratos (2)'!$C17) -> 600 | L17: =SUMIFS(Qtde_Oper_Plantio_Tratos!W:W,Qtde_Oper_Plantio_Tratos!$F:$F,'Dimensionamento Tratos (2)'!$B17,Qtde_Oper_Plantio_Tratos!$I:$I,'Dimensionamento Tratos (2)'!$C17) -> 310 | M17: =SUMIFS(Qtde_Oper_Plantio_Tratos!X:X,Qtde_Oper_Plantio_Tratos!$F:$F,'Dimensionamento Tratos (2)'!$B17,Qtde_Oper_Plantio_Tratos!$I:$I,'Dimensionamento Tratos (2)'!$C17) -> 250 | N17: =SUMIFS(Qtde_Oper_Plantio_Tratos!Y:Y,Qtde_Oper_Plantio_Tratos!$F:$F,'Dimensionamento Tratos (2)'!$B17,Qtde_Oper_Plantio_Tratos!$I:$I,'Dimensionamento Tratos (2)'!$C17) -> 250 | O17: =SUMIFS(Qtde_Oper_Plantio_Tratos!Z:Z,Qtde_Oper_Plantio_Tratos!$F:$F,'Dimensionamento Tratos (2)'!$B17,Qtde_Oper_Plantio_Tratos!$I:$I,'Dimensionamento Tratos (2)'!$C17) -> 250 | P17: =SUMIFS(Qtde_Oper_Plantio_Tratos!AA:AA,Qtde_Oper_Plantio_Tratos!$F:$F,'Dimensionamento Tratos (2)'!$B17,Qtde_Oper_Plantio_Tratos!$I:$I,'Dimensionamento Tratos (2)'!$C17) -> 250 | Q17: =SUMIFS(Qtde_Oper_Plantio_Tratos!AB:AB,Qtde_Oper_Plantio_Tratos!$F:$F,'Dimensionamento Tratos (2)'!$B17,Qtde_Oper_Plantio_Tratos!$I:$I,'Dimensionamento Tratos (2)'!$C17) -> 3569.224
C18: Proprio | D18: Trator Tratos | E18: =IF($C18="Proprio",IFERROR(E17/(_xlfn.XLOOKUP(E$6,$E$68:$Q$68,$E$69:$Q$69)*_xlfn.XLOOKUP($B17,$C$52:$C$64,$E$52:$E$64)),0),0) -> 0 | F18: =IF($C18="Proprio",IFERROR(F17/(_xlfn.XLOOKUP(F$6,$E$68:$Q$68,$E$69:$Q$69)*_xlfn.XLOOKUP($B17,$C$52:$C$64,$E$52:$E$64)),0),0) -> 0 | G18: =IF($C18="Proprio",IFERROR(G17/(_xlfn.XLOOKUP(G$6,$E$68:$Q$68,$E$69:$Q$69)*_xlfn.XLOOKUP($B17,$C$52:$C$64,$E$52:$E$64)),0),0) -> 0.33807775 | H18: =IF($C18="Proprio",IFERROR(H17/(_xlfn.XLOOKUP(H$6,$E$68:$Q$68,$E$69:$Q$69)*_xlfn.XLOOKUP($B17,$C$52:$C$64,$E$52:$E$64)),0),0) -> 0 | I18: =IF($C18="Proprio",IFERROR(I17/(_xlfn.XLOOKUP(I$6,$E$68:$Q$68,$E$69:$Q$69)*_xlfn.XLOOKUP($B17,$C$52:$C$64,$E$52:$E$64)),0),0) -> 0.29680979 | J18: =IF($C18="Proprio",IFERROR(J17/(_xlfn.XLOOKUP(J$6,$E$68:$Q$68,$E$69:$Q$69)*_xlfn.XLOOKUP($B17,$C$52:$C$64,$E$52:$E$64)),0),0) -> 0.36335879 | K18: =IF($C18="Proprio",IFERROR(K17/(_xlfn.XLOOKUP(K$6,$E$68:$Q$68,$E$69:$Q$69)*_xlfn.XLOOKUP($B17,$C$52:$C$64,$E$52:$E$64)),0),0) -> 0.42042862 | L18: =IF($C18="Proprio",IFERROR(L17/(_xlfn.XLOOKUP(L$6,$E$68:$Q$68,$E$69:$Q$69)*_xlfn.XLOOKUP($B17,$C$52:$C$64,$E$52:$E$64)),0),0) -> 0.24284241 | ... P18: =IF($C18="Proprio",IFERROR(P17/(_xlfn.XLOOKUP(P$6,$E$68:$Q$68,$E$69:$Q$69)*_xlfn.XLOOKUP($B17,$C$52:$C$64,$E$52:$E$64)),0),0) -> 0.22608067 | Q18: =IFERROR(Q17/(_xlfn.XLOOKUP(Q$6,$E$68:$Q$68,$E$69:$Q$69)*_xlfn.XLOOKUP($B17,$C$52:$C$64,$E$52:$E$64)),0) -> 0.22638711
B19: 1031 | C19: TRATCSF | D19: =_xlfn.XLOOKUP(B19,Apoio!A:A,Apoio!B:B) -> 1ª Aplicação De Herbicida | E19: =SUMIFS(Qtde_Oper_Plantio_Tratos!P:P,Qtde_Oper_Plantio_Tratos!$F:$F,'Dimensionamento Tratos (2)'!$B19,Qtde_Oper_Plantio_Tratos!$I:$I,'Dimensionamento Tratos (2)'!$C19) -> 0 | F19: =SUMIFS(Qtde_Oper_Plantio_Tratos!Q:Q,Qtde_Oper_Plantio_Tratos!$F:$F,'Dimensionamento Tratos (2)'!$B19,Qtde_Oper_Plantio_Tratos!$I:$I,'Dimensionamento Tratos (2)'!$C19) -> 0 | G19: =SUMIFS(Qtde_Oper_Plantio_Tratos!R:R,Qtde_Oper_Plantio_Tratos!$F:$F,'Dimensionamento Tratos (2)'!$B19,Qtde_Oper_Plantio_Tratos!$I:$I,'Dimensionamento Tratos (2)'!$C19) -> 100 | H19: =SUMIFS(Qtde_Oper_Plantio_Tratos!S:S,Qtde_Oper_Plantio_Tratos!$F:$F,'Dimensionamento Tratos (2)'!$B19,Qtde_Oper_Plantio_Tratos!$I:$I,'Dimensionamento Tratos (2)'!$C19) -> 0 | I19: =SUMIFS(Qtde_Oper_Plantio_Tratos!T:T,Qtde_Oper_Plantio_Tratos!$F:$F,'Dimensionamento Tratos (2)'!$B19,Qtde_Oper_Plantio_Tratos!$I:$I,'Dimensionamento Tratos (2)'!$C19) -> 100 | J19: =SUMIFS(Qtde_Oper_Plantio_Tratos!U:U,Qtde_Oper_Plantio_Tratos!$F:$F,'Dimensionamento Tratos (2)'!$B19,Qtde_Oper_Plantio_Tratos!$I:$I,'Dimensionamento Tratos (2)'!$C19) -> 100 | K19: =SUMIFS(Qtde_Oper_Plantio_Tratos!V:V,Qtde_Oper_Plantio_Tratos!$F:$F,'Dimensionamento Tratos (2)'!$B19,Qtde_Oper_Plantio_Tratos!$I:$I,'Dimensionamento Tratos (2)'!$C19) -> 100 | L19: =SUMIFS(Qtde_Oper_Plantio_Tratos!W:W,Qtde_Oper_Plantio_Tratos!$F:$F,'Dimensionamento Tratos (2)'!$B19,Qtde_Oper_Plantio_Tratos!$I:$I,'Dimensionamento Tratos (2)'!$C19) -> 0 | M19: =SUMIFS(Qtde_Oper_Plantio_Tratos!X:X,Qtde_Oper_Plantio_Tratos!$F:$F,'Dimensionamento Tratos (2)'!$B19,Qtde_Oper_Plantio_Tratos!$I:$I,'Dimensionamento Tratos (2)'!$C19) -> 0 | N19: =SUMIFS(Qtde_Oper_Plantio_Tratos!Y:Y,Qtde_Oper_Plantio_Tratos!$F:$F,'Dimensionamento Tratos (2)'!$B19,Qtde_Oper_Plantio_Tratos!$I:$I,'Dimensionamento Tratos (2)'!$C19) -> 0 | O19: =SUMIFS(Qtde_Oper_Plantio_Tratos!Z:Z,Qtde_Oper_Plantio_Tratos!$F:$F,'Dimensionamento Tratos (2)'!$B19,Qtde_Oper_Plantio_Tratos!$I:$I,'Dimensionamento Tratos (2)'!$C19) -> 0 | P19: =SUMIFS(Qtde_Oper_Plantio_Tratos!AA:AA,Qtde_Oper_Plantio_Tratos!$F:$F,'Dimensionamento Tratos (2)'!$B19,Qtde_Oper_Plantio_Tratos!$I:$I,'Dimensionamento Tratos (2)'!$C19) -> 0 | Q19: =SUM(E19:P19) -> 400
C20: Proprio | E20: =IF($C20="Proprio",IFERROR(E19/(_xlfn.XLOOKUP(E$6,$E$68:$Q$68,$E$69:$Q$69)*_xlfn.XLOOKUP($B19,$C$52:$C$64,$E$52:$E$64)),0),0) -> 0 | F20: =IF($C20="Proprio",IFERROR(F19/(_xlfn.XLOOKUP(F$6,$E$68:$Q$68,$E$69:$Q$69)*_xlfn.XLOOKUP($B19,$C$52:$C$64,$E$52:$E$64)),0),0) -> 0 | G20: =IF($C20="Proprio",IFERROR(G19/(_xlfn.XLOOKUP(G$6,$E$68:$Q$68,$E$69:$Q$69)*_xlfn.XLOOKUP($B19,$C$52:$C$64,$E$52:$E$64)),0),0) -> 0.047400613 | H20: =IF($C20="Proprio",IFERROR(H19/(_xlfn.XLOOKUP(H$6,$E$68:$Q$68,$E$69:$Q$69)*_xlfn.XLOOKUP($B19,$C$52:$C$64,$E$52:$E$64)),0),0) -> 0 | I20: =IF($C20="Proprio",IFERROR(I19/(_xlfn.XLOOKUP(I$6,$E$68:$Q$68,$E$69:$Q$69)*_xlfn.XLOOKUP($B19,$C$52:$C$64,$E$52:$E$64)),0),0) -> 0.044077296 | J20: =IF($C20="Proprio",IFERROR(J19/(_xlfn.XLOOKUP(J$6,$E$68:$Q$68,$E$69:$Q$69)*_xlfn.XLOOKUP($B19,$C$52:$C$64,$E$52:$E$64)),0),0) -> 0.048638886 | K20: =IF($C20="Proprio",IFERROR(K19/(_xlfn.XLOOKUP(K$6,$E$68:$Q$68,$E$69:$Q$69)*_xlfn.XLOOKUP($B19,$C$52:$C$64,$E$52:$E$64)),0),0) -> 0.054490151 | L20: =IF($C20="Proprio",IFERROR(L19/(_xlfn.XLOOKUP(L$6,$E$68:$Q$68,$E$69:$Q$69)*_xlfn.XLOOKUP($B19,$C$52:$C$64,$E$52:$E$64)),0),0) -> 0 | ... P20: =IF($C20="Proprio",IFERROR(P19/(_xlfn.XLOOKUP(P$6,$E$68:$Q$68,$E$69:$Q$69)*_xlfn.XLOOKUP($B19,$C$52:$C$64,$E$52:$E$64)),0),0) -> 0 | Q20: =IFERROR(Q19/(_xlfn.XLOOKUP(Q$6,$E$68:$Q$68,$E$69:$Q$69)*_xlfn.XLOOKUP($B19,$C$52:$C$64,$E$52:$E$64)),0) -> 0.019729445
B21: 1032 | C21: TRATCSP | D21: =_xlfn.XLOOKUP(B21,Apoio!A:A,Apoio!B:B) -> Aplicação De Inseticida | E21: =SUMIFS(Qtde_Oper_Plantio_Tratos!P:P,Qtde_Oper_Plantio_Tratos!$F:$F,'Dimensionamento Tratos (2)'!$B21,Qtde_Oper_Plantio_Tratos!$I:$I,'Dimensionamento Tratos (2)'!$C21) -> 149.03 | F21: =SUMIFS(Qtde_Oper_Plantio_Tratos!Q:Q,Qtde_Oper_Plantio_Tratos!$F:$F,'Dimensionamento Tratos (2)'!$B21,Qtde_Oper_Plantio_Tratos!$I:$I,'Dimensionamento Tratos (2)'!$C21) -> 411.48 | G21: =SUMIFS(Qtde_Oper_Plantio_Tratos!R:R,Qtde_Oper_Plantio_Tratos!$F:$F,'Dimensionamento Tratos (2)'!$B21,Qtde_Oper_Plantio_Tratos!$I:$I,'Dimensionamento Tratos (2)'!$C21) -> 211.61 | H21: =SUMIFS(Qtde_Oper_Plantio_Tratos!S:S,Qtde_Oper_Plantio_Tratos!$F:$F,'Dimensionamento Tratos (2)'!$B21,Qtde_Oper_Plantio_Tratos!$I:$I,'Dimensionamento Tratos (2)'!$C21) -> 9.96 | I21: =SUMIFS(Qtde_Oper_Plantio_Tratos!T:T,Qtde_Oper_Plantio_Tratos!$F:$F,'Dimensionamento Tratos (2)'!$B21,Qtde_Oper_Plantio_Tratos!$I:$I,'Dimensionamento Tratos (2)'!$C21) -> 106.19 | J21: =SUMIFS(Qtde_Oper_Plantio_Tratos!U:U,Qtde_Oper_Plantio_Tratos!$F:$F,'Dimensionamento Tratos (2)'!$B21,Qtde_Oper_Plantio_Tratos!$I:$I,'Dimensionamento Tratos (2)'!$C21) -> 65.32 | K21: =SUMIFS(Qtde_Oper_Plantio_Tratos!V:V,Qtde_Oper_Plantio_Tratos!$F:$F,'Dimensionamento Tratos (2)'!$B21,Qtde_Oper_Plantio_Tratos!$I:$I,'Dimensionamento Tratos (2)'!$C21) -> 511.76 | L21: =SUMIFS(Qtde_Oper_Plantio_Tratos!W:W,Qtde_Oper_Plantio_Tratos!$F:$F,'Dimensionamento Tratos (2)'!$B21,Qtde_Oper_Plantio_Tratos!$I:$I,'Dimensionamento Tratos (2)'!$C21) -> 10.95 | M21: =SUMIFS(Qtde_Oper_Plantio_Tratos!X:X,Qtde_Oper_Plantio_Tratos!$F:$F,'Dimensionamento Tratos (2)'!$B21,Qtde_Oper_Plantio_Tratos!$I:$I,'Dimensionamento Tratos (2)'!$C21) -> 0 | N21: =SUMIFS(Qtde_Oper_Plantio_Tratos!Y:Y,Qtde_Oper_Plantio_Tratos!$F:$F,'Dimensionamento Tratos (2)'!$B21,Qtde_Oper_Plantio_Tratos!$I:$I,'Dimensionamento Tratos (2)'!$C21) -> 0 | O21: =SUMIFS(Qtde_Oper_Plantio_Tratos!Z:Z,Qtde_Oper_Plantio_Tratos!$F:$F,'Dimensionamento Tratos (2)'!$B21,Qtde_Oper_Plantio_Tratos!$I:$I,'Dimensionamento Tratos (2)'!$C21) -> 0 | P21: =SUMIFS(Qtde_Oper_Plantio_Tratos!AA:AA,Qtde_Oper_Plantio_Tratos!$F:$F,'Dimensionamento Tratos (2)'!$B21,Qtde_Oper_Plantio_Tratos!$I:$I,'Dimensionamento Tratos (2)'!$C21) -> 0 | Q21: =SUMIFS(Qtde_Oper_Plantio_Tratos!AB:AB,Qtde_Oper_Plantio_Tratos!$F:$F,'Dimensionamento Tratos (2)'!$B21,Qtde_Oper_Plantio_Tratos!$I:$I,'Dimensionamento Tratos (2)'!$C21) -> 1476.3
C22: Proprio | E22: =IF($C22="Proprio",IFERROR(E21/(_xlfn.XLOOKUP(E$6,$E$68:$Q$68,$E$69:$Q$69)*_xlfn.XLOOKUP($B21,$C$52:$C$64,$E$52:$E$64)),0),0) -> 0.078547511 | F22: =IF($C22="Proprio",IFERROR(F21/(_xlfn.XLOOKUP(F$6,$E$68:$Q$68,$E$69:$Q$69)*_xlfn.XLOOKUP($B21,$C$52:$C$64,$E$52:$E$64)),0),0) -> 0.19701262 | G22: =IF($C22="Proprio",IFERROR(G21/(_xlfn.XLOOKUP(G$6,$E$68:$Q$68,$E$69:$Q$69)*_xlfn.XLOOKUP($B21,$C$52:$C$64,$E$52:$E$64)),0),0) -> 0.098232031 | H22: =IF($C22="Proprio",IFERROR(H21/(_xlfn.XLOOKUP(H$6,$E$68:$Q$68,$E$69:$Q$69)*_xlfn.XLOOKUP($B21,$C$52:$C$64,$E$52:$E$64)),0),0) -> 0.0042333352 | I22: =IF($C22="Proprio",IFERROR(I21/(_xlfn.XLOOKUP(I$6,$E$68:$Q$68,$E$69:$Q$69)*_xlfn.XLOOKUP($B21,$C$52:$C$64,$E$52:$E$64)),0),0) -> 0.045838621 | J22: =IF($C22="Proprio",IFERROR(J21/(_xlfn.XLOOKUP(J$6,$E$68:$Q$68,$E$69:$Q$69)*_xlfn.XLOOKUP($B21,$C$52:$C$64,$E$52:$E$64)),0),0) -> 0.031114497 | K22: =IF($C22="Proprio",IFERROR(K21/(_xlfn.XLOOKUP(K$6,$E$68:$Q$68,$E$69:$Q$69)*_xlfn.XLOOKUP($B21,$C$52:$C$64,$E$52:$E$64)),0),0) -> 0.27309725 | L22: =IF($C22="Proprio",IFERROR(L21/(_xlfn.XLOOKUP(L$6,$E$68:$Q$68,$E$69:$Q$69)*_xlfn.XLOOKUP($B21,$C$52:$C$64,$E$52:$E$64)),0),0) -> 0.0065326131 | ... P22: =IF($C22="Proprio",IFERROR(P21/(_xlfn.XLOOKUP(P$6,$E$68:$Q$68,$E$69:$Q$69)*_xlfn.XLOOKUP($B21,$C$52:$C$64,$E$52:$E$64)),0),0) -> 0 | Q22: =IFERROR(Q21/(_xlfn.XLOOKUP(Q$6,$E$68:$Q$68,$E$69:$Q$69)*_xlfn.XLOOKUP($B21,$C$52:$C$64,$E$52:$E$64)),0) -> 0.071311978
B23: 1090 | C23: TRATCSP | D23: =_xlfn.XLOOKUP(B23,Apoio!A:A,Apoio!B:B) -> Repasse Aplicação Herbicida | E23: =SUMIFS(Qtde_Oper_Plantio_Tratos!P:P,Qtde_Oper_Plantio_Tratos!$F:$F,'Dimensionamento Tratos (2)'!$B23,Qtde_Oper_Plantio_Tratos!$I:$I,'Dimensionamento Tratos (2)'!$C23) -> 105 | F23: =SUMIFS(Qtde_Oper_Plantio_Tratos!Q:Q,Qtde_Oper_Plantio_Tratos!$F:$F,'Dimensionamento Tratos (2)'!$B23,Qtde_Oper_Plantio_Tratos!$I:$I,'Dimensionamento Tratos (2)'!$C23) -> 98 | G23: =SUMIFS(Qtde_Oper_Plantio_Tratos!R:R,Qtde_Oper_Plantio_Tratos!$F:$F,'Dimensionamento Tratos (2)'!$B23,Qtde_Oper_Plantio_Tratos!$I:$I,'Dimensionamento Tratos (2)'!$C23) -> 63 | H23: =SUMIFS(Qtde_Oper_Plantio_Tratos!S:S,Qtde_Oper_Plantio_Tratos!$F:$F,'Dimensionamento Tratos (2)'!$B23,Qtde_Oper_Plantio_Tratos!$I:$I,'Dimensionamento Tratos (2)'!$C23) -> 100 | I23: =SUMIFS(Qtde_Oper_Plantio_Tratos!T:T,Qtde_Oper_Plantio_Tratos!$F:$F,'Dimensionamento Tratos (2)'!$B23,Qtde_Oper_Plantio_Tratos!$I:$I,'Dimensionamento Tratos (2)'!$C23) -> 100 | J23: =SUMIFS(Qtde_Oper_Plantio_Tratos!U:U,Qtde_Oper_Plantio_Tratos!$F:$F,'Dimensionamento Tratos (2)'!$B23,Qtde_Oper_Plantio_Tratos!$I:$I,'Dimensionamento Tratos (2)'!$C23) -> 84 | K23: =SUMIFS(Qtde_Oper_Plantio_Tratos!V:V,Qtde_Oper_Plantio_Tratos!$F:$F,'Dimensionamento Tratos (2)'!$B23,Qtde_Oper_Plantio_Tratos!$I:$I,'Dimensionamento Tratos (2)'!$C23) -> 196 | L23: =SUMIFS(Qtde_Oper_Plantio_Tratos!W:W,Qtde_Oper_Plantio_Tratos!$F:$F,'Dimensionamento Tratos (2)'!$B23,Qtde_Oper_Plantio_Tratos!$I:$I,'Dimensionamento Tratos (2)'!$C23) -> 0 | M23: =SUMIFS(Qtde_Oper_Plantio_Tratos!X:X,Qtde_Oper_Plantio_Tratos!$F:$F,'Dimensionamento Tratos (2)'!$B23,Qtde_Oper_Plantio_Tratos!$I:$I,'Dimensionamento Tratos (2)'!$C23) -> 100 | N23: =SUMIFS(Qtde_Oper_Plantio_Tratos!Y:Y,Qtde_Oper_Plantio_Tratos!$F:$F,'Dimensionamento Tratos (2)'!$B23,Qtde_Oper_Plantio_Tratos!$I:$I,'Dimensionamento Tratos (2)'!$C23) -> 100 | O23: =SUMIFS(Qtde_Oper_Plantio_Tratos!Z:Z,Qtde_Oper_Plantio_Tratos!$F:$F,'Dimensionamento Tratos (2)'!$B23,Qtde_Oper_Plantio_Tratos!$I:$I,'Dimensionamento Tratos (2)'!$C23) -> 100 | P23: =SUMIFS(Qtde_Oper_Plantio_Tratos!AA:AA,Qtde_Oper_Plantio_Tratos!$F:$F,'Dimensionamento Tratos (2)'!$B23,Qtde_Oper_Plantio_Tratos!$I:$I,'Dimensionamento Tratos (2)'!$C23) -> 100 | Q23: =SUM(E23:P23) -> 1146
C24: Proprio | E24: =IF($C24="Proprio",IFERROR(E23/(_xlfn.XLOOKUP(E$6,$E$68:$Q$68,$E$69:$Q$69)*_xlfn.XLOOKUP($B23,$C$52:$C$64,$E$52:$E$64)),0),0) -> 0.24573493 | F24: =IF($C24="Proprio",IFERROR(F23/(_xlfn.XLOOKUP(F$6,$E$68:$Q$68,$E$69:$Q$69)*_xlfn.XLOOKUP($B23,$C$52:$C$64,$E$52:$E$64)),0),0) -> 0.20834844 | G24: =IF($C24="Proprio",IFERROR(G23/(_xlfn.XLOOKUP(G$6,$E$68:$Q$68,$E$69:$Q$69)*_xlfn.XLOOKUP($B23,$C$52:$C$64,$E$52:$E$64)),0),0) -> 0.12986028 | H24: =IF($C24="Proprio",IFERROR(H23/(_xlfn.XLOOKUP(H$6,$E$68:$Q$68,$E$69:$Q$69)*_xlfn.XLOOKUP($B23,$C$52:$C$64,$E$52:$E$64)),0),0) -> 0.18873054 | I24: =IF($C24="Proprio",IFERROR(I23/(_xlfn.XLOOKUP(I$6,$E$68:$Q$68,$E$69:$Q$69)*_xlfn.XLOOKUP($B23,$C$52:$C$64,$E$52:$E$64)),0),0) -> 0.19167558 | J24: =IF($C24="Proprio",IFERROR(J23/(_xlfn.XLOOKUP(J$6,$E$68:$Q$68,$E$69:$Q$69)*_xlfn.XLOOKUP($B23,$C$52:$C$64,$E$52:$E$64)),0),0) -> 0.17767027 | K24: =IF($C24="Proprio",IFERROR(K23/(_xlfn.XLOOKUP(K$6,$E$68:$Q$68,$E$69:$Q$69)*_xlfn.XLOOKUP($B23,$C$52:$C$64,$E$52:$E$64)),0),0) -> 0.46443606 | L24: =IF($C24="Proprio",IFERROR(L23/(_xlfn.XLOOKUP(L$6,$E$68:$Q$68,$E$69:$Q$69)*_xlfn.XLOOKUP($B23,$C$52:$C$64,$E$52:$E$64)),0),0) -> 0 | ... P24: =IF($C24="Proprio",IFERROR(P23/(_xlfn.XLOOKUP(P$6,$E$68:$Q$68,$E$69:$Q$69)*_xlfn.XLOOKUP($B23,$C$52:$C$64,$E$52:$E$64)),0),0) -> 0.3058104 | Q24: =IFERROR(Q23/(_xlfn.XLOOKUP(Q$6,$E$68:$Q$68,$E$69:$Q$69)*_xlfn.XLOOKUP($B23,$C$52:$C$64,$E$52:$E$64)),0) -> 0.24580536
B25: 1091 | C25: TRATCSP | D25: =_xlfn.XLOOKUP(B25,Apoio!A:A,Apoio!B:B) -> Aplic. Herb Man - Cat. Quimíca | E25: =SUMIFS(Qtde_Oper_Plantio_Tratos!P:P,Qtde_Oper_Plantio_Tratos!$F:$F,'Dimensionamento Tratos (2)'!$B25,Qtde_Oper_Plantio_Tratos!$I:$I,'Dimensionamento Tratos (2)'!$C25) -> 177.2696 | F25: =SUMIFS(Qtde_Oper_Plantio_Tratos!Q:Q,Qtde_Oper_Plantio_Tratos!$F:$F,'Dimensionamento Tratos (2)'!$B25,Qtde_Oper_Plantio_Tratos!$I:$I,'Dimensionamento Tratos (2)'!$C25) -> 308.2264 | G25: =SUMIFS(Qtde_Oper_Plantio_Tratos!R:R,Qtde_Oper_Plantio_Tratos!$F:$F,'Dimensionamento Tratos (2)'!$B25,Qtde_Oper_Plantio_Tratos!$I:$I,'Dimensionamento Tratos (2)'!$C25) -> 126.7744 | H25: =SUMIFS(Qtde_Oper_Plantio_Tratos!S:S,Qtde_Oper_Plantio_Tratos!$F:$F,'Dimensionamento Tratos (2)'!$B25,Qtde_Oper_Plantio_Tratos!$I:$I,'Dimensionamento Tratos (2)'!$C25) -> 0 | I25: =SUMIFS(Qtde_Oper_Plantio_Tratos!T:T,Qtde_Oper_Plantio_Tratos!$F:$F,'Dimensionamento Tratos (2)'!$B25,Qtde_Oper_Plantio_Tratos!$I:$I,'Dimensionamento Tratos (2)'!$C25) -> 119.6912 | J25: =SUMIFS(Qtde_Oper_Plantio_Tratos!U:U,Qtde_Oper_Plantio_Tratos!$F:$F,'Dimensionamento Tratos (2)'!$B25,Qtde_Oper_Plantio_Tratos!$I:$I,'Dimensionamento Tratos (2)'!$C25) -> 132.7856 | K25: =SUMIFS(Qtde_Oper_Plantio_Tratos!V:V,Qtde_Oper_Plantio_Tratos!$F:$F,'Dimensionamento Tratos (2)'!$B25,Qtde_Oper_Plantio_Tratos!$I:$I,'Dimensionamento Tratos (2)'!$C25) -> 149.4912 | L25: =SUMIFS(Qtde_Oper_Plantio_Tratos!W:W,Qtde_Oper_Plantio_Tratos!$F:$F,'Dimensionamento Tratos (2)'!$B25,Qtde_Oper_Plantio_Tratos!$I:$I,'Dimensionamento Tratos (2)'!$C25) -> 40 | M25: =SUMIFS(Qtde_Oper_Plantio_Tratos!X:X,Qtde_Oper_Plantio_Tratos!$F:$F,'Dimensionamento Tratos (2)'!$B25,Qtde_Oper_Plantio_Tratos!$I:$I,'Dimensionamento Tratos (2)'!$C25) -> 40 | N25: =SUMIFS(Qtde_Oper_Plantio_Tratos!Y:Y,Qtde_Oper_Plantio_Tratos!$F:$F,'Dimensionamento Tratos (2)'!$B25,Qtde_Oper_Plantio_Tratos!$I:$I,'Dimensionamento Tratos (2)'!$C25) -> 40 | O25: =SUMIFS(Qtde_Oper_Plantio_Tratos!Z:Z,Qtde_Oper_Plantio_Tratos!$F:$F,'Dimensionamento Tratos (2)'!$B25,Qtde_Oper_Plantio_Tratos!$I:$I,'Dimensionamento Tratos (2)'!$C25) -> 40 | P25: =SUMIFS(Qtde_Oper_Plantio_Tratos!AA:AA,Qtde_Oper_Plantio_Tratos!$F:$F,'Dimensionamento Tratos (2)'!$B25,Qtde_Oper_Plantio_Tratos!$I:$I,'Dimensionamento Tratos (2)'!$C25) -> 40 | Q25: =SUMIFS(Qtde_Oper_Plantio_Tratos!AB:AB,Qtde_Oper_Plantio_Tratos!$F:$F,'Dimensionamento Tratos (2)'!$B25,Qtde_Oper_Plantio_Tratos!$I:$I,'Dimensionamento Tratos (2)'!$C25) -> 1214.2384
C26: Proprio | E26: =IF($C26="Proprio",IFERROR(E25/(_xlfn.XLOOKUP(E$6,$E$68:$Q$68,$E$69:$Q$69)*_xlfn.XLOOKUP($B25,$C$52:$C$64,$E$52:$E$64)),0),0) -> 4.1486983 | F26: =IF($C26="Proprio",IFERROR(F25/(_xlfn.XLOOKUP(F$6,$E$68:$Q$68,$E$69:$Q$69)*_xlfn.XLOOKUP($B25,$C$52:$C$64,$E$52:$E$64)),0),0) -> 6.5529071 | G26: =IF($C26="Proprio",IFERROR(G25/(_xlfn.XLOOKUP(G$6,$E$68:$Q$68,$E$69:$Q$69)*_xlfn.XLOOKUP($B25,$C$52:$C$64,$E$52:$E$64)),0),0) -> 2.6131682 | H26: =IF($C26="Proprio",IFERROR(H25/(_xlfn.XLOOKUP(H$6,$E$68:$Q$68,$E$69:$Q$69)*_xlfn.XLOOKUP($B25,$C$52:$C$64,$E$52:$E$64)),0),0) -> 0 | I26: =IF($C26="Proprio",IFERROR(I25/(_xlfn.XLOOKUP(I$6,$E$68:$Q$68,$E$69:$Q$69)*_xlfn.XLOOKUP($B25,$C$52:$C$64,$E$52:$E$64)),0),0) -> 2.294188 | J26: =IF($C26="Proprio",IFERROR(J25/(_xlfn.XLOOKUP(J$6,$E$68:$Q$68,$E$69:$Q$69)*_xlfn.XLOOKUP($B25,$C$52:$C$64,$E$52:$E$64)),0),0) -> 2.8085777 | K26: =IF($C26="Proprio",IFERROR(K25/(_xlfn.XLOOKUP(K$6,$E$68:$Q$68,$E$69:$Q$69)*_xlfn.XLOOKUP($B25,$C$52:$C$64,$E$52:$E$64)),0),0) -> 3.5423012 | L26: =IF($C26="Proprio",IFERROR(L25/(_xlfn.XLOOKUP(L$6,$E$68:$Q$68,$E$69:$Q$69)*_xlfn.XLOOKUP($B25,$C$52:$C$64,$E$52:$E$64)),0),0) -> 1.0596237 | ... P26: =IF($C26="Proprio",IFERROR(P25/(_xlfn.XLOOKUP(P$6,$E$68:$Q$68,$E$69:$Q$69)*_xlfn.XLOOKUP($B25,$C$52:$C$64,$E$52:$E$64)),0),0) -> 1.2232416 | Q26: =IFERROR(Q25/(_xlfn.XLOOKUP(Q$6,$E$68:$Q$68,$E$69:$Q$69)*_xlfn.XLOOKUP($B25,$C$52:$C$64,$E$52:$E$64)),0) -> 2.604418
D27: =_xlfn.XLOOKUP(B27,Apoio!A:A,Apoio!B:B) -> 0 | E27: =SUMIFS(Qtde_Oper_Plantio_Tratos!P:P,Qtde_Oper_Plantio_Tratos!$F:$F,'Dimensionamento Tratos (2)'!$B27,Qtde_Oper_Plantio_Tratos!$I:$I,'Dimensionamento Tratos (2)'!$C27) -> 0 | F27: =SUMIFS(Qtde_Oper_Plantio_Tratos!Q:Q,Qtde_Oper_Plantio_Tratos!$F:$F,'Dimensionamento Tratos (2)'!$B27,Qtde_Oper_Plantio_Tratos!$I:$I,'Dimensionamento Tratos (2)'!$C27) -> 0 | G27: =SUMIFS(Qtde_Oper_Plantio_Tratos!R:R,Qtde_Oper_Plantio_Tratos!$F:$F,'Dimensionamento Tratos (2)'!$B27,Qtde_Oper_Plantio_Tratos!$I:$I,'Dimensionamento Tratos (2)'!$C27) -> 0 | H27: =SUMIFS(Qtde_Oper_Plantio_Tratos!S:S,Qtde_Oper_Plantio_Tratos!$F:$F,'Dimensionamento Tratos (2)'!$B27,Qtde_Oper_Plantio_Tratos!$I:$I,'Dimensionamento Tratos (2)'!$C27) -> 0 | I27: =SUMIFS(Qtde_Oper_Plantio_Tratos!T:T,Qtde_Oper_Plantio_Tratos!$F:$F,'Dimensionamento Tratos (2)'!$B27,Qtde_Oper_Plantio_Tratos!$I:$I,'Dimensionamento Tratos (2)'!$C27) -> 0 | J27: =SUMIFS(Qtde_Oper_Plantio_Tratos!U:U,Qtde_Oper_Plantio_Tratos!$F:$F,'Dimensionamento Tratos (2)'!$B27,Qtde_Oper_Plantio_Tratos!$I:$I,'Dimensionamento Tratos (2)'!$C27) -> 0 | K27: =SUMIFS(Qtde_Oper_Plantio_Tratos!V:V,Qtde_Oper_Plantio_Tratos!$F:$F,'Dimensionamento Tratos (2)'!$B27,Qtde_Oper_Plantio_Tratos!$I:$I,'Dimensionamento Tratos (2)'!$C27) -> 0 | L27: =SUMIFS(Qtde_Oper_Plantio_Tratos!W:W,Qtde_Oper_Plantio_Tratos!$F:$F,'Dimensionamento Tratos (2)'!$B27,Qtde_Oper_Plantio_Tratos!$I:$I,'Dimensionamento Tratos (2)'!$C27) -> 0 | M27: =SUMIFS(Qtde_Oper_Plantio_Tratos!X:X,Qtde_Oper_Plantio_Tratos!$F:$F,'Dimensionamento Tratos (2)'!$B27,Qtde_Oper_Plantio_Tratos!$I:$I,'Dimensionamento Tratos (2)'!$C27) -> 0 | N27: =SUMIFS(Qtde_Oper_Plantio_Tratos!Y:Y,Qtde_Oper_Plantio_Tratos!$F:$F,'Dimensionamento Tratos (2)'!$B27,Qtde_Oper_Plantio_Tratos!$I:$I,'Dimensionamento Tratos (2)'!$C27) -> 0 | O27: =SUMIFS(Qtde_Oper_Plantio_Tratos!Z:Z,Qtde_Oper_Plantio_Tratos!$F:$F,'Dimensionamento Tratos (2)'!$B27,Qtde_Oper_Plantio_Tratos!$I:$I,'Dimensionamento Tratos (2)'!$C27) -> 0 | P27: =SUMIFS(Qtde_Oper_Plantio_Tratos!AA:AA,Qtde_Oper_Plantio_Tratos!$F:$F,'Dimensionamento Tratos (2)'!$B27,Qtde_Oper_Plantio_Tratos!$I:$I,'Dimensionamento Tratos (2)'!$C27) -> 0 | Q27: =SUM(E27:P27) -> 0
E28: =IF($C28="Proprio",IFERROR(E27/(_xlfn.XLOOKUP(E$6,$E$68:$Q$68,$E$69:$Q$69)*_xlfn.XLOOKUP($B27,$C$52:$C$64,$E$52:$E$64)),0),0) -> 0 | F28: =IF($C28="Proprio",IFERROR(F27/(_xlfn.XLOOKUP(F$6,$E$68:$Q$68,$E$69:$Q$69)*_xlfn.XLOOKUP($B27,$C$52:$C$64,$E$52:$E$64)),0),0) -> 0 | G28: =IF($C28="Proprio",IFERROR(G27/(_xlfn.XLOOKUP(G$6,$E$68:$Q$68,$E$69:$Q$69)*_xlfn.XLOOKUP($B27,$C$52:$C$64,$E$52:$E$64)),0),0) -> 0 | H28: =IF($C28="Proprio",IFERROR(H27/(_xlfn.XLOOKUP(H$6,$E$68:$Q$68,$E$69:$Q$69)*_xlfn.XLOOKUP($B27,$C$52:$C$64,$E$52:$E$64)),0),0) -> 0 | I28: =IF($C28="Proprio",IFERROR(I27/(_xlfn.XLOOKUP(I$6,$E$68:$Q$68,$E$69:$Q$69)*_xlfn.XLOOKUP($B27,$C$52:$C$64,$E$52:$E$64)),0),0) -> 0 | J28: =IF($C28="Proprio",IFERROR(J27/(_xlfn.XLOOKUP(J$6,$E$68:$Q$68,$E$69:$Q$69)*_xlfn.XLOOKUP($B27,$C$52:$C$64,$E$52:$E$64)),0),0) -> 0 | K28: =IF($C28="Proprio",IFERROR(K27/(_xlfn.XLOOKUP(K$6,$E$68:$Q$68,$E$69:$Q$69)*_xlfn.XLOOKUP($B27,$C$52:$C$64,$E$52:$E$64)),0),0) -> 0 | L28: =IF($C28="Proprio",IFERROR(L27/(_xlfn.XLOOKUP(L$6,$E$68:$Q$68,$E$69:$Q$69)*_xlfn.XLOOKUP($B27,$C$52:$C$64,$E$52:$E$64)),0),0) -> 0 | ... P28: =IF($C28="Proprio",IFERROR(P27/(_xlfn.XLOOKUP(P$6,$E$68:$Q$68,$E$69:$Q$69)*_xlfn.XLOOKUP($B27,$C$52:$C$64,$E$52:$E$64)),0),0) -> 0 | Q28: =IFERROR(Q27/(_xlfn.XLOOKUP(Q$6,$E$68:$Q$68,$E$69:$Q$69)*_xlfn.XLOOKUP($B27,$C$52:$C$64,$E$52:$E$64)),0) -> 0
D29: =_xlfn.XLOOKUP(B29,Apoio!A:A,Apoio!B:B) -> 0 | E29: =SUMIFS(Qtde_Oper_Plantio_Tratos!P:P,Qtde_Oper_Plantio_Tratos!$F:$F,'Dimensionamento Tratos (2)'!$B29,Qtde_Oper_Plantio_Tratos!$I:$I,'Dimensionamento Tratos (2)'!$C29) -> 0 | F29: =SUMIFS(Qtde_Oper_Plantio_Tratos!Q:Q,Qtde_Oper_Plantio_Tratos!$F:$F,'Dimensionamento Tratos (2)'!$B29,Qtde_Oper_Plantio_Tratos!$I:$I,'Dimensionamento Tratos (2)'!$C29) -> 0 | G29: =SUMIFS(Qtde_Oper_Plantio_Tratos!R:R,Qtde_Oper_Plantio_Tratos!$F:$F,'Dimensionamento Tratos (2)'!$B29,Qtde_Oper_Plantio_Tratos!$I:$I,'Dimensionamento Tratos (2)'!$C29) -> 0 | H29: =SUMIFS(Qtde_Oper_Plantio_Tratos!S:S,Qtde_Oper_Plantio_Tratos!$F:$F,'Dimensionamento Tratos (2)'!$B29,Qtde_Oper_Plantio_Tratos!$I:$I,'Dimensionamento Tratos (2)'!$C29) -> 0 | I29: =SUMIFS(Qtde_Oper_Plantio_Tratos!T:T,Qtde_Oper_Plantio_Tratos!$F:$F,'Dimensionamento Tratos (2)'!$B29,Qtde_Oper_Plantio_Tratos!$I:$I,'Dimensionamento Tratos (2)'!$C29) -> 0 | J29: =SUMIFS(Qtde_Oper_Plantio_Tratos!U:U,Qtde_Oper_Plantio_Tratos!$F:$F,'Dimensionamento Tratos (2)'!$B29,Qtde_Oper_Plantio_Tratos!$I:$I,'Dimensionamento Tratos (2)'!$C29) -> 0 | K29: =SUMIFS(Qtde_Oper_Plantio_Tratos!V:V,Qtde_Oper_Plantio_Tratos!$F:$F,'Dimensionamento Tratos (2)'!$B29,Qtde_Oper_Plantio_Tratos!$I:$I,'Dimensionamento Tratos (2)'!$C29) -> 0 | L29: =SUMIFS(Qtde_Oper_Plantio_Tratos!W:W,Qtde_Oper_Plantio_Tratos!$F:$F,'Dimensionamento Tratos (2)'!$B29,Qtde_Oper_Plantio_Tratos!$I:$I,'Dimensionamento Tratos (2)'!$C29) -> 0 | M29: =SUMIFS(Qtde_Oper_Plantio_Tratos!X:X,Qtde_Oper_Plantio_Tratos!$F:$F,'Dimensionamento Tratos (2)'!$B29,Qtde_Oper_Plantio_Tratos!$I:$I,'Dimensionamento Tratos (2)'!$C29) -> 0 | N29: =SUMIFS(Qtde_Oper_Plantio_Tratos!Y:Y,Qtde_Oper_Plantio_Tratos!$F:$F,'Dimensionamento Tratos (2)'!$B29,Qtde_Oper_Plantio_Tratos!$I:$I,'Dimensionamento Tratos (2)'!$C29) -> 0 | O29: =SUMIFS(Qtde_Oper_Plantio_Tratos!Z:Z,Qtde_Oper_Plantio_Tratos!$F:$F,'Dimensionamento Tratos (2)'!$B29,Qtde_Oper_Plantio_Tratos!$I:$I,'Dimensionamento Tratos (2)'!$C29) -> 0 | P29: =SUMIFS(Qtde_Oper_Plantio_Tratos!AA:AA,Qtde_Oper_Plantio_Tratos!$F:$F,'Dimensionamento Tratos (2)'!$B29,Qtde_Oper_Plantio_Tratos!$I:$I,'Dimensionamento Tratos (2)'!$C29) -> 0 | Q29: =SUMIFS(Qtde_Oper_Plantio_Tratos!AB:AB,Qtde_Oper_Plantio_Tratos!$F:$F,'Dimensionamento Tratos (2)'!$B29,Qtde_Oper_Plantio_Tratos!$I:$I,'Dimensionamento Tratos (2)'!$C29) -> 0
E30: =IF($C30="Proprio",IFERROR(E29/(_xlfn.XLOOKUP(E$6,$E$68:$Q$68,$E$69:$Q$69)*_xlfn.XLOOKUP($B29,$C$52:$C$64,$E$52:$E$64)),0),0) -> 0 | F30: =IF($C30="Proprio",IFERROR(F29/(_xlfn.XLOOKUP(F$6,$E$68:$Q$68,$E$69:$Q$69)*_xlfn.XLOOKUP($B29,$C$52:$C$64,$E$52:$E$64)),0),0) -> 0 | G30: =IF($C30="Proprio",IFERROR(G29/(_xlfn.XLOOKUP(G$6,$E$68:$Q$68,$E$69:$Q$69)*_xlfn.XLOOKUP($B29,$C$52:$C$64,$E$52:$E$64)),0),0) -> 0 | H30: =IF($C30="Proprio",IFERROR(H29/(_xlfn.XLOOKUP(H$6,$E$68:$Q$68,$E$69:$Q$69)*_xlfn.XLOOKUP($B29,$C$52:$C$64,$E$52:$E$64)),0),0) -> 0 | I30: =IF($C30="Proprio",IFERROR(I29/(_xlfn.XLOOKUP(I$6,$E$68:$Q$68,$E$69:$Q$69)*_xlfn.XLOOKUP($B29,$C$52:$C$64,$E$52:$E$64)),0),0) -> 0 | J30: =IF($C30="Proprio",IFERROR(J29/(_xlfn.XLOOKUP(J$6,$E$68:$Q$68,$E$69:$Q$69)*_xlfn.XLOOKUP($B29,$C$52:$C$64,$E$52:$E$64)),0),0) -> 0 | K30: =IF($C30="Proprio",IFERROR(K29/(_xlfn.XLOOKUP(K$6,$E$68:$Q$68,$E$69:$Q$69)*_xlfn.XLOOKUP($B29,$C$52:$C$64,$E$52:$E$64)),0),0) -> 0 | L30: =IF($C30="Proprio",IFERROR(L29/(_xlfn.XLOOKUP(L$6,$E$68:$Q$68,$E$69:$Q$69)*_xlfn.XLOOKUP($B29,$C$52:$C$64,$E$52:$E$64)),0),0) -> 0 | ... P30: =IF($C30="Proprio",IFERROR(P29/(_xlfn.XLOOKUP(P$6,$E$68:$Q$68,$E$69:$Q$69)*_xlfn.XLOOKUP($B29,$C$52:$C$64,$E$52:$E$64)),0),0) -> 0 | Q30: =IFERROR(Q29/(_xlfn.XLOOKUP(Q$6,$E$68:$Q$68,$E$69:$Q$69)*_xlfn.XLOOKUP($B29,$C$52:$C$64,$E$52:$E$64)),0) -> 0
D31: =_xlfn.XLOOKUP(B31,Apoio!A:A,Apoio!B:B) -> 0 | E31: =SUMIFS(Qtde_Oper_Plantio_Tratos!P:P,Qtde_Oper_Plantio_Tratos!$F:$F,'Dimensionamento Tratos (2)'!$B31,Qtde_Oper_Plantio_Tratos!$I:$I,'Dimensionamento Tratos (2)'!$C31) -> 0 | F31: =SUMIFS(Qtde_Oper_Plantio_Tratos!Q:Q,Qtde_Oper_Plantio_Tratos!$F:$F,'Dimensionamento Tratos (2)'!$B31,Qtde_Oper_Plantio_Tratos!$I:$I,'Dimensionamento Tratos (2)'!$C31) -> 0 | G31: =SUMIFS(Qtde_Oper_Plantio_Tratos!R:R,Qtde_Oper_Plantio_Tratos!$F:$F,'Dimensionamento Tratos (2)'!$B31,Qtde_Oper_Plantio_Tratos!$I:$I,'Dimensionamento Tratos (2)'!$C31) -> 0 | H31: =SUMIFS(Qtde_Oper_Plantio_Tratos!S:S,Qtde_Oper_Plantio_Tratos!$F:$F,'Dimensionamento Tratos (2)'!$B31,Qtde_Oper_Plantio_Tratos!$I:$I,'Dimensionamento Tratos (2)'!$C31) -> 0 | I31: =SUMIFS(Qtde_Oper_Plantio_Tratos!T:T,Qtde_Oper_Plantio_Tratos!$F:$F,'Dimensionamento Tratos (2)'!$B31,Qtde_Oper_Plantio_Tratos!$I:$I,'Dimensionamento Tratos (2)'!$C31) -> 0 | J31: =SUMIFS(Qtde_Oper_Plantio_Tratos!U:U,Qtde_Oper_Plantio_Tratos!$F:$F,'Dimensionamento Tratos (2)'!$B31,Qtde_Oper_Plantio_Tratos!$I:$I,'Dimensionamento Tratos (2)'!$C31) -> 0 | K31: =SUMIFS(Qtde_Oper_Plantio_Tratos!V:V,Qtde_Oper_Plantio_Tratos!$F:$F,'Dimensionamento Tratos (2)'!$B31,Qtde_Oper_Plantio_Tratos!$I:$I,'Dimensionamento Tratos (2)'!$C31) -> 0 | L31: =SUMIFS(Qtde_Oper_Plantio_Tratos!W:W,Qtde_Oper_Plantio_Tratos!$F:$F,'Dimensionamento Tratos (2)'!$B31,Qtde_Oper_Plantio_Tratos!$I:$I,'Dimensionamento Tratos (2)'!$C31) -> 0 | M31: =SUMIFS(Qtde_Oper_Plantio_Tratos!X:X,Qtde_Oper_Plantio_Tratos!$F:$F,'Dimensionamento Tratos (2)'!$B31,Qtde_Oper_Plantio_Tratos!$I:$I,'Dimensionamento Tratos (2)'!$C31) -> 0 | N31: =SUMIFS(Qtde_Oper_Plantio_Tratos!Y:Y,Qtde_Oper_Plantio_Tratos!$F:$F,'Dimensionamento Tratos (2)'!$B31,Qtde_Oper_Plantio_Tratos!$I:$I,'Dimensionamento Tratos (2)'!$C31) -> 0 | O31: =SUMIFS(Qtde_Oper_Plantio_Tratos!Z:Z,Qtde_Oper_Plantio_Tratos!$F:$F,'Dimensionamento Tratos (2)'!$B31,Qtde_Oper_Plantio_Tratos!$I:$I,'Dimensionamento Tratos (2)'!$C31) -> 0 | P31: =SUMIFS(Qtde_Oper_Plantio_Tratos!AA:AA,Qtde_Oper_Plantio_Tratos!$F:$F,'Dimensionamento Tratos (2)'!$B31,Qtde_Oper_Plantio_Tratos!$I:$I,'Dimensionamento Tratos (2)'!$C31) -> 0 | Q31: =SUM(E31:P31) -> 0
E32: =IF($C32="Proprio",IFERROR(E31/(_xlfn.XLOOKUP(E$6,$E$68:$Q$68,$E$69:$Q$69)*_xlfn.XLOOKUP($B31,$C$52:$C$64,$E$52:$E$64)),0),0) -> 0 | F32: =IF($C32="Proprio",IFERROR(F31/(_xlfn.XLOOKUP(F$6,$E$68:$Q$68,$E$69:$Q$69)*_xlfn.XLOOKUP($B31,$C$52:$C$64,$E$52:$E$64)),0),0) -> 0 | G32: =IF($C32="Proprio",IFERROR(G31/(_xlfn.XLOOKUP(G$6,$E$68:$Q$68,$E$69:$Q$69)*_xlfn.XLOOKUP($B31,$C$52:$C$64,$E$52:$E$64)),0),0) -> 0 | H32: =IF($C32="Proprio",IFERROR(H31/(_xlfn.XLOOKUP(H$6,$E$68:$Q$68,$E$69:$Q$69)*_xlfn.XLOOKUP($B31,$C$52:$C$64,$E$52:$E$64)),0),0) -> 0 | I32: =IF($C32="Proprio",IFERROR(I31/(_xlfn.XLOOKUP(I$6,$E$68:$Q$68,$E$69:$Q$69)*_xlfn.XLOOKUP($B31,$C$52:$C$64,$E$52:$E$64)),0),0) -> 0 | J32: =IF($C32="Proprio",IFERROR(J31/(_xlfn.XLOOKUP(J$6,$E$68:$Q$68,$E$69:$Q$69)*_xlfn.XLOOKUP($B31,$C$52:$C$64,$E$52:$E$64)),0),0) -> 0 | K32: =IF($C32="Proprio",IFERROR(K31/(_xlfn.XLOOKUP(K$6,$E$68:$Q$68,$E$69:$Q$69)*_xlfn.XLOOKUP($B31,$C$52:$C$64,$E$52:$E$64)),0),0) -> 0 | L32: =IF($C32="Proprio",IFERROR(L31/(_xlfn.XLOOKUP(L$6,$E$68:$Q$68,$E$69:$Q$69)*_xlfn.XLOOKUP($B31,$C$52:$C$64,$E$52:$E$64)),0),0) -> 0 | ... P32: =IF($C32="Proprio",IFERROR(P31/(_xlfn.XLOOKUP(P$6,$E$68:$Q$68,$E$69:$Q$69)*_xlfn.XLOOKUP($B31,$C$52:$C$64,$E$52:$E$64)),0),0) -> 0 | Q32: =IFERROR(Q31/(_xlfn.XLOOKUP(Q$6,$E$68:$Q$68,$E$69:$Q$69)*_xlfn.XLOOKUP($B31,$C$52:$C$64,$E$52:$E$64)),0) -> 0
D33: Nec_Tratores | E33: =ROUNDUP(SUM(E32,E30,E28,E26,E24,E22,E20,E18,E16,E14,E12,E10,E8),0) -> 21 | F33: =ROUNDUP(SUM(F32,F30,F28,F26,F24,F22,F20,F18,F16,F14,F12,F10,F8),0) -> 27 | G33: =ROUNDUP(SUM(G32,G30,G28,G26,G24,G22,G20,G18,G16,G14,G12,G10,G8),0) -> 20 | H33: =ROUNDUP(SUM(H32,H30,H28,H26,H24,H22,H20,H18,H16,H14,H12,H10,H8),0) -> 14 | I33: =ROUNDUP(SUM(I32,I30,I28,I26,I24,I22,I20,I18,I16,I14,I12,I10,I8),0) -> 15 | J33: =ROUNDUP(SUM(J32,J30,J28,J26,J24,J22,J20,J18,J16,J14,J12,J10,J8),0) -> 19 | K33: =ROUNDUP(SUM(K32,K30,K28,K26,K24,K22,K20,K18,K16,K14,K12,K10,K8),0) -> 29 | L33: =ROUNDUP(SUM(L32,L30,L28,L26,L24,L22,L20,L18,L16,L14,L12,L10,L8),0) -> 19 | ... Q33: =ROUNDUP(SUM(Q32,Q30,Q28,Q26,Q24,Q22,Q20,Q18,Q16,Q14,Q12,Q10,Q8),0) -> 17
D34: Disp_Tratores | E34: =E48 -> 14 | F34: =F48 -> 14 | G34: =G48 -> 14 | H34: =H48 -> 14 | I34: =I48 -> 14 | J34: =J48 -> 14 | K34: =K48 -> 14 | L34: =L48 -> 14 | ... Q34: =Q48 -> 21
D37: Inventário Máquinas
D38: Mês | E38: 45748 | F38: 45778 | G38: 45809 | H38: 45839 | I38: 45870 | J38: 45901 | K38: 45931 | L38: 45962 | M38: 45992 | N38: 46023 | O38: 46054 | P38: 46082 | Q38: Total
D39: Trator Herbicida | E39: 3 | F39: 3 | G39: 3 | H39: 3 | I39: 3 | J39: 3 | K39: 3 | L39: 3 | M39: 3 | N39: 3 | O39: 3 | P39: 3 | Q39: 3
D40: Trator Torta | Q40: 3
D41: Trator Quebra Lombo | E41: 3 | F41: 3 | G41: 3 | H41: 3 | I41: 3 | J41: 3 | K41: 3 | L41: 3 | M41: 3 | N41: 3 | O41: 3 | P41: 3 | Q41: 3
D42: Trator Cultivo | E42: 0 | F42: 0 | G42: 0 | H42: 0 | I42: 0 | J42: 0 | K42: 0 | L42: 0 | M42: 0 | N42: 0 | O42: 0 | P42: 0 | Q42: 3
D43: Trator Catação | E43: 2 | F43: 2 | G43: 2 | H43: 2 | I43: 2 | J43: 2 | K43: 2 | L43: 2 | M43: 2 | N43: 2 | O43: 2 | P43: 2 | Q43: 3
D44: Trator Apl Inseticida Em Profundidade | E44: 4 | F44: 4 | G44: 4 | H44: 4 | I44: 4 | J44: 4 | K44: 4 | L44: 4 | M44: 4 | N44: 4 | O44: 4 | P44: 4 | Q44: 4
D45: Carreador | E45: 2 | F45: 2 | G45: 2 | H45: 2 | I45: 2 | J45: 2 | K45: 2 | L45: 2 | M45: 2 | N45: 2 | O45: 2 | P45: 2 | Q45: 2
...

Sheet Plano Horas
B2: Operação | C2: CD_Operação | D2: DE_Operação | E2: Turnos | F2: Horas de atividade dia | G2: Disp. Mecânica | H2: Deslocamento | I2: Troca de Turno | J2: Check-list | K2: Abast.e/ou lubrificação | L2: Refeição | M2: Mudança de área | N2: Manobra | O2: Abast. Insumo | P2: Total horas disponivel dia para produção
E3: qtd. | F3: h | G3: % | H3: h/dia | I3: h/dia | J3: h/dia | K3: h/dia | L3: h/dia | M3: h/dia | N3: % | O3: h/dia | P3: h
F4: 0.33333333 | H4: 0.0625 | J4: 0.0069444444 | K4: 0.0069444444 | L4: 0.041666667 | M4: 0.020833333 | N4: 0 | O4: 0
B5: PREPARO DE SOLO | C5: 1001 | D5: TERRACEAMENTO | E5: 1 | F5: =IF($E5=1,$F$4,IF($E5=2,$F$4*2,($F$4*3)-0.0001)) -> 0.33333333 | G5: 0.9 | H5: 0.027777778 | J5: =E5*$J$4 -> 0.0069444444 | K5: 0.013888889 | L5: =$L$4*$E5 -> 0.041666667 | M5: 0.03125 | N5: 0 | O5: 0 | P5: =((F5*24)*G5)-(SUM(H5:O5)*24) -> 4.2833333
C6: 1004 | D6: CURVA EM NÍVEL | E6: 1 | F6: =IF($E6=1,$F$4,IF($E6=2,$F$4*2,($F$4*3)-0.0001)) -> 0.33333333 | G6: 0.9 | H6: 0.027777778 | J6: =E6*$J$4 -> 0.0069444444 | K6: 0.013888889 | L6: =$L$4*$E6 -> 0.041666667 | M6: 0.03125 | N6: 0 | O6: 0 | P6: =((F6*24)*G6)-(SUM(H6:O6)*24) -> 4.2833333
C7: 1005 | D7: SISTEMATIZAÇÃO | E7: 1 | F7: =IF($E7=1,$F$4,IF($E7=2,$F$4*2,($F$4*3)-0.0001)) -> 0.33333333 | G7: 0.9 | H7: 0.027777778 | J7: =E7*$J$4 -> 0.0069444444 | K7: 0.013888889 | L7: =$L$4*$E7 -> 0.041666667 | M7: 0.03125 | N7: 0 | O7: 0 | P7: =((F7*24)*G7)-(SUM(H7:O7)*24) -> 4.2833333
C8: 1011 | D8: ARAÇÃO | E8: 1 | F8: =IF($E8=1,$F$4,IF($E8=2,$F$4*2,($F$4*3)-0.0001)) -> 0.33333333 | G8: 0.9 | H8: 0.027777778 | J8: =E8*$J$4 -> 0.0069444444 | K8: 0.013888889 | L8: =$L$4*$E8 -> 0.041666667 | M8: 0.03125 | N8: 0 | O8: 0 | P8: =((F8*24)*G8)-(SUM(H8:O8)*24) -> 4.2833333
C9: 1013 | D9: GRADAGEM ARADORA | E9: 1 | F9: =IF($E9=1,$F$4,IF($E9=2,$F$4*2,($F$4*3)-0.0001)) -> 0.33333333 | G9: 0.85 | H9: 0.027777778 | J9: =E9*$J$4 -> 0.0069444444 | K9: 0.013888889 | L9: =$L$4*$E9 -> 0.041666667 | M9: 0.03125 | N9: 0 | O9: 0 | P9: =((F9*24)*G9)-(SUM(H9:O9)*24) -> 3.8833333
C10: 1014 | D10: GRADAGEM INTERMEDIÁRIA | E10: 1 | F10: =IF($E10=1,$F$4,IF($E10=2,$F$4*2,($F$4*3)-0.0001)) -> 0.33333333 | G10: 0.85 | H10: 0.027777778 | J10: =E10*$J$4 -> 0.0069444444 | K10: 0.013888889 | L10: =$L$4*$E10 -> 0.041666667 | M10: 0.03125 | N10: 0 | O10: 0 | P10: =((F10*24)*G10)-(SUM(H10:O10)*24) -> 3.8833333
C11: 1015 | D11: GRADAGEM NIVELADORA | E11: 1 | F11: =IF($E11=1,$F$4,IF($E11=2,$F$4*2,($F$4*3)-0.0001)) -> 0.33333333 | G11: 0.85 | H11: 0.027777778 | J11: =E11*$J$4 -> 0.0069444444 | K11: 0.013888889 | L11: =$L$4*$E11 -> 0.041666667 | M11: 0.03125 | N11: 0 | O11: 0 | P11: =((F11*24)*G11)-(SUM(H11:O11)*24) -> 3.8833333
C12: 1016 | D12: SUBSOLAGEM | E12: 1 | F12: =IF($E12=1,$F$4,IF($E12=2,$F$4*2,($F$4*3)-0.0001)) -> 0.33333333 | G12: 0.85 | H12: 0.027777778 | J12: =E12*$J$4 -> 0.0069444444 | K12: 0.013888889 | L12: =$L$4*$E12 -> 0.041666667 | M12: 0.03125 | N12: 0 | O12: 0 | P12: =((F12*24)*G12)-(SUM(H12:O12)*24) -> 3.8833333
C13: 1024 | D13: ENLEIRAMENTO DE PALHA | E13: 1 | F13: =IF($E13=1,$F$4,IF($E13=2,$F$4*2,($F$4*3)-0.0001)) -> 0.33333333 | G13: 0.85 | H13: 0.027777778 | J13: =E13*$J$4 -> 0.0069444444 | K13: 0.013888889 | L13: =$L$4*$E13 -> 0.041666667 | M13: 0.03125 | N13: 0 | O13: 0 | P13: =((F13*24)*G13)-(SUM(H13:O13)*24) -> 3.8833333
C14: 1026 | D14: APLICAÇÃO DE FOSFATO | E14: 1 | F14: =IF($E14=1,$F$4,IF($E14=2,$F$4*2,($F$4*3)-0.0001)) -> 0.33333333 | G14: 0.85 | H14: 0.027777778 | J14: =E14*$J$4 -> 0.0069444444 | K14: 0.013888889 | L14: =$L$4*$E14 -> 0.041666667 | M14: 0.03125 | N14: 0 | O14: 0.0069444444 | P14: =((F14*24)*G14)-(SUM(H14:O14)*24) -> 3.7166667
C15: 1028 | D15: APLICAÇÃO DE CALCÁRIO | E15: 1 | F15: =IF($E15=1,$F$4,IF($E15=2,$F$4*2,($F$4*3)-0.0001)) -> 0.33333333 | G15: 0.85 | H15: 0.027777778 | J15: =E15*$J$4 -> 0.0069444444 | K15: 0.013888889 | L15: =$L$4*$E15 -> 0.041666667 | M15: 0.03125 | N15: 0 | O15: 0.0069444444 | P15: =((F15*24)*G15)-(SUM(H15:O15)*24) -> 3.7166667
C16: 1029 | D16: APLICAÇÃO DE GESSO | E16: 1 | F16: =IF($E16=1,$F$4,IF($E16=2,$F$4*2,($F$4*3)-0.0001)) -> 0.33333333 | G16: 0.85 | H16: 0.027777778 | J16: =E16*$J$4 -> 0.0069444444 | K16: 0.013888889 | L16: =$L$4*$E16 -> 0.041666667 | M16: 0.03125 | N16: 0 | O16: 0.0069444444 | P16: =((F16*24)*G16)-(SUM(H16:O16)*24) -> 3.7166667
C17: 1033 | D17: APLICAÇÃO DE TORTA DE FILTRO | E17: 1 | F17: =IF($E17=1,$F$4,IF($E17=2,$F$4*2,($F$4*3)-0.0001)) -> 0.33333333 | G17: 0.85 | H17: 0.027777778 | J17: =E17*$J$4 -> 0.0069444444 | K17: 0.013888889 | L17: =$L$4*$E17 -> 0.041666667 | M17: 0.03125 | N17: 0 | O17: 0.0069444444 | P17: =((F17*24)*G17)-(SUM(H17:O17)*24) -> 3.7166667
... C19: 1061 | D19: ENFARDAMENTO DE PALHA | E19: 1 | F19: =IF($E19=1,$F$4,IF($E19=2,$F$4*2,($F$4*3)-0.0001)) -> 0.33333333 | G19: 0.85 | H19: 0.027777778 | J19: =E19*$J$4 -> 0.0069444444 | K19: 0.013888889 | L19: =$L$4*$E19 -> 0.041666667 | M19: 0.03125 | N19: 0 | O19: 0 | P19: =((F19*24)*G19)-(SUM(H19:O19)*24) -> 3.8833333
B20: TRATOS CULTURAIS | C20: 1020 | D20: QUEBRA DE LOMBO | E20: 1 | F20: =IF($E20=1,$F$4,IF($E20=2,$F$4*2,($F$4*3)-0.0001)) -> 0.33333333 | G20: 0.9 | H20: 0.027777778 | J20: =E20*$J$4 -> 0.0069444444 | K20: 0.013888889 | L20: =$L$4*$E20 -> 0.041666667 | M20: 0.03125 | N20: 0 | O20: 0.0069444444 | P20: =((F20*24)*G20)-(SUM(H20:O20)*24) -> 4.1166667
C21: 1022 | D21: CULTIVO (adubação soca) | E21: 1 | F21: =IF($E21=1,$F$4,IF($E21=2,$F$4*2,($F$4*3)-0.0001)) -> 0.33333333 | G21: 0.9 | H21: 0.027777778 | J21: =E21*$J$4 -> 0.0069444444 | K21: 0.013888889 | L21: =$L$4*$E21 -> 0.041666667 | M21: 0.03125 | N21: 0 | O21: 0.010416667 | P21: =((F21*24)*G21)-(SUM(H21:O21)*24) -> 4.0333333
C22: 1031 | D22: APLICAÇÃO DE HERBICIDA | E22: 1 | F22: =IF($E22=1,$F$4,IF($E22=2,$F$4*2,($F$4*3)-0.0001)) -> 0.33333333 | G22: 0.9 | H22: 0.027777778 | J22: =E22*$J$4 -> 0.0069444444 | K22: 0.013888889 | L22: =$L$4*$E22 -> 0.041666667 | M22: 0.03125 | N22: 0 | O22: 0.013888889 | P22: =((F22*24)*G22)-(SUM(H22:O22)*24) -> 3.95
C23: 1032 | D23: APLICAÇÃO DE INSETICIDA | E23: 1 | F23: =IF($E23=1,$F$4,IF($E23=2,$F$4*2,($F$4*3)-0.0001)) -> 0.33333333 | G23: 0.9 | H23: 0.027777778 | J23: =E23*$J$4 -> 0.0069444444 | K23: 0.013888889 | L23: =$L$4*$E23 -> 0.041666667 | M23: 0.03125 | N23: 0 | O23: 0.010416667 | P23: =((F23*24)*G23)-(SUM(H23:O23)*24) -> 4.0333333
C24: 1073 | D24: Apl Inseticida Em Profundidade | E24: 1 | F24: =IF($E24=1,$F$4,IF($E24=2,$F$4*2,($F$4*3)-0.0001)) -> 0.33333333 | G24: 0.9 | H24: 0.027777778 | J24: =E24*$J$4 -> 0.0069444444 | K24: 0.013888889 | L24: =$L$4*$E24 -> 0.041666667 | M24: 0.03125 | N24: 0 | O24: 0.010416667 | P24: =((F24*24)*G24)-(SUM(H24:O24)*24) -> 4.0333333
C25: 1035 | D25: APLIC DE VINHAÇA VIA CAMINHÃO | E25: 1 | F25: =IF($E25=1,$F$4,IF($E25=2,$F$4*2,($F$4*3)-0.0001)) -> 0.33333333 | G25: 0.9 | H25: 0 | J25: =E25*$J$4 -> 0.0069444444 | K25: 0.013888889 | L25: =$L$4*$E25 -> 0.041666667 | M25: 0.03125 | N25: 0 | O25: 0 | P25: =((F25*24)*G25)-(SUM(H25:O25)*24) -> 4.95
C26: 1050 | D26: TRAÇÃO MOTOBOMBA (canal) | E26: 1 | F26: =IF($E26=1,$F$4,IF($E26=2,$F$4*2,($F$4*3)-0.0001)) -> 0.33333333 | G26: 0.9 | H26: 0 | J26: =E26*$J$4 -> 0.0069444444 | K26: 0.013888889 | L26: =$L$4*$E26 -> 0.041666667 | M26: 0.03125 | N26: 0 | O26: 0 | P26: =((F26*24)*G26)-(SUM(H26:O26)*24) -> 4.95
C27: 1078 | E27: 1 | F27: =IF($E27=1,$F$4,IF($E27=2,$F$4*2,($F$4*3)-0.0001)) -> 0.33333333 | G27: 0.8 | H27: 0.027777778 | J27: =E27*$J$4 -> 0.0069444444 | K27: 0.013888889 | L27: =$L$4*$E27 -> 0.041666667 | M27: 0.03125 | N27: 0 | O27: 0.010416667 | P27: =((F27*24)*G27)-(SUM(H27:O27)*24) -> 3.2333333
C28: 1071 | E28: 1 | F28: =IF($E28=1,$F$4,IF($E28=2,$F$4*2,($F$4*3)-0.0001)) -> 0.33333333 | G28: 0.85 | H28: 0.027777778 | J28: =E28*$J$4 -> 0.0069444444 | K28: 0.013888889 | L28: =$L$4*$E28 -> 0.041666667 | M28: 0.03125 | N28: 0 | O28: 0.010416667 | P28: =((F28*24)*G28)-(SUM(H28:O28)*24) -> 3.6333333
