Workbook

Sheet OPERÇÃO
C1: FROTA | D1: MODELO | E1: GRUPO | F1: STATUS
C2: 11116 | D2: =_xlfn.XLOOKUP(C2,BASE!A:A,BASE!B:B,2,0) -> NEW HOLLAND T7.245 | E2: PREPARO DE SOLO | F2: Intermediaria
C3: 11118 | D3: =_xlfn.XLOOKUP(C3,BASE!A:A,BASE!B:B,2,0) -> NEW HOLLAND TL 85 | E3: PREPARO DE SOLO | F3: Enleiramento de palha
C4: 11121 | D4: =_xlfn.XLOOKUP(C4,BASE!A:A,BASE!B:B,2,0) -> NEW HOLLAND T7 240 | E4: PREPARO DE SOLO | F4: Terraceamento
C5: 11125 | D5: NEW HOLLAND TL5 | E5: TRATOS CULTURAIS | F5: Aplicação de Herbicida
C6: 11216 | D6: =_xlfn.XLOOKUP(C6,BASE!A:A,BASE!B:B,2,0) -> NEW HOLLAND T7.245 | E6: PREPARO DE SOLO | F6: Intermediaria
C7: 11218 | D7: =_xlfn.XLOOKUP(C7,BASE!A:A,BASE!B:B,2,0) -> NEW HOLLAND TL 85 | E7: PREPARO DE SOLO | F7: Sulcação
C8: 11221 | D8: =_xlfn.XLOOKUP(C8,BASE!A:A,BASE!B:B,2,0) -> NEW HOLLAND T7 240 | E8: VIHAÇA | F8: Aplicação de vinhaça com fertilizante
C9: 11225 | D9: NEW HOLLAND TL5 | E9: TRATOS CULTURAIS | F9: Aplicação de Herbicida
C10: 11316 | D10: =_xlfn.XLOOKUP(C10,BASE!A:A,BASE!B:B,2,0) -> NEW HOLLAND TL 85 | E10: VINHAÇA | F10: Oficina Externa
C11: 11318 | D11: =_xlfn.XLOOKUP(C11,BASE!A:A,BASE!B:B,2,0) -> NEW HOLLAND T7.175 | E11: PREPARO DE SOLO | F11: Aplicação Mista
C12: 11321 | D12: =_xlfn.XLOOKUP(C12,BASE!A:A,BASE!B:B,2,0) -> NEW HOLLAND T7 240 | E12: PREPARO DE SOLO | F12: Aplicação Mista
C13: 11416 | D13: =_xlfn.XLOOKUP(C13,BASE!A:A,BASE!B:B,2,0) -> NEW HOLLAND T7.245 | E13: VINHAÇA | F13: Oficina (Verificar motor)
C14: 11324 | D14: TRATOR CASE - PUMA 155 | E14: TRATOS CULTURAIS | F14: Quebra lombo
C15: 11418 | D15: =_xlfn.XLOOKUP(C15,BASE!A:A,BASE!B:B,2,0) -> NEW HOLLAND T6.130 | E15: TRATOS CULTURAIS | F15: Aguardando Manutenção terceiro (Implemento 523)
C16: 11421 | D16: =_xlfn.XLOOKUP(C16,BASE!A:A,BASE!B:B,2,0) -> NEW HOLLAND T7 240 | E16: PREPARO DE SOLO | F16: Oficina
C17: 11424 | D17: TRATOR CASE - PUMA 155 | E17: TRATOS CULTURAIS | F17: Quebra lombo
C18: 11516 | D18: =_xlfn.XLOOKUP(C18,BASE!A:A,BASE!B:B,2,0) -> NEW HOLLAND T7.260 | E18: VINHAÇA | F18: Aplicação de vinhaça com fertilizante
C19: 11518 | D19: =_xlfn.XLOOKUP(C19,BASE!A:A,BASE!B:B,2,0) -> NEW HOLLAND T6.130 | E19: TRATOS CULTURAIS | F19: Cultivo
C20: 11524 | D20: TRATOR CASE - PUMA 155 | E20: TRATOS CULTURAIS | F20: Quebra lombo
C21: 11616 | D21: =_xlfn.XLOOKUP(C21,BASE!A:A,BASE!B:B,2,0) -> NEW HOLLAND T7.260 | E21: VINHAÇA | F21: Oficina - Revisar transmissão
C22: 11618 | D22: =_xlfn.XLOOKUP(C22,BASE!A:A,BASE!B:B,2,0) -> NEW HOLLAND T6.130 | E22: TRATOS CULTURAIS | F22: Aplicação inseticida
C23: 11718 | D23: =_xlfn.XLOOKUP(C23,BASE!A:A,BASE!B:B,2,0) -> NEW HOLLAND T6.130 | E23: TRATOS CULTURAIS | F23: Cultivo
C24: 11124 | D24: TRATOR CASE - FARMALL 80 | E24: TRATOS CULTURAIS | F24: Catação quimica
C25: 11224 | D25: TRATOR CASE - FARMALL 80 | E25: TRATOS CULTURAIS | F25: Vazamento na ponteira da barra
C26: 435 | D26: =_xlfn.XLOOKUP(C26,BASE!A:A,BASE!B:B,2,0) -> MOTOBOMBA VINHAÇA - MWM | E26: VINHAÇA | F26: Sem Operação
C27: 34 | D27: =_xlfn.XLOOKUP(C27,BASE!A:A,BASE!B:B,2,0) -> MOTOBOMBA VINHAÇA - MERCEDES | E27: VINHAÇA | F27: Sem Operação
C28: 91 | D28: =_xlfn.XLOOKUP(C28,BASE!A:A,BASE!B:B,2,0) -> MOTOBOMBA VINHAÇA | E28: VINHAÇA | F28: Sem Operação
C29: 32 | D29: =_xlfn.XLOOKUP(C29,BASE!A:A,BASE!B:B,2,0) -> MOTOBOMBA VINHAÇA | E29: VINHAÇA | F29: Sem Operação
C30: 33 | D30: =_xlfn.XLOOKUP(C30,BASE!A:A,BASE!B:B,2,0) -> MOTOBOMBA VINHAÇA | E30: VINHAÇA | F30: Sem Operação
C31: 329 | D31: =_xlfn.XLOOKUP(C31,BASE!A:A,BASE!B:B,2,0) -> NEW HOLLAND W 170B - PA CARREGADEIRA | E31: PREPARO DE SOLO | F31: Carregando - Terra - Bagaço - Outros
C32: 340 | D32: VALTRA BF - 3020 H | E32: TRATOS CULTURAIS | F32: Aguardando eletricista ( Bitola trincada e verificar abertura de sessão da barra do aplicador)
C33: 527 | D33: =_xlfn.XLOOKUP(C33,BASE!A:A,BASE!B:B,2,0) -> NEW HOLLAND RG 170B VHP - NIVELADORA | E33: PREPARO DE SOLO | F33: Conservação de estrada
C34: 532 | D34: =_xlfn.XLOOKUP(C34,BASE!A:A,BASE!B:B,2,0) -> VALTRA BH - 180 HI FLOW | E34: VINHAÇA | F34: Sem Operação (offline)
C35: 533 | D35: VALTRA BH 180 | E35: VINHAÇA | F35: Manutenção Oficina
C36: 535 | D36: =_xlfn.XLOOKUP(C36,BASE!A:A,BASE!B:B,2,0) -> VALTRA BH - 180 HI FLOW | E36: VINHAÇA | F36: Offline / pátio
C37: 537 | D37: =_xlfn.XLOOKUP(C37,BASE!A:A,BASE!B:B,2,0) -> VALTRA BH - 180 HI FLOW | E37: VINHAÇA | F37: Reforma
C38: 543 | D38: =_xlfn.XLOOKUP(C38,BASE!A:A,BASE!B:B,2,0) -> NEW HOLLAND W 130 ZB - PA CARREGADEIRA | E38: PREPARO DE SOLO | F38: Verificar mangueira da bomba injetora (Rachou)
C39: 724 | D39: =_xlfn.XLOOKUP(C39,BASE!A:A,BASE!B:B,2,0) -> NEW HOLLAND T8-385 | E39: PREPARO DE SOLO | F39: Gradagem Aradora
C40: 726 | D40: =_xlfn.XLOOKUP(C40,BASE!A:A,BASE!B:B,2,0) -> NEW HOLLAND TM 7040 | E40: PREPARO DE SOLO | F40: Sem operação
...

Sheet BASE
A1: FROTA | B1: MODELO | C1: CATEGORIA_OPERACIONAL | D1: GRUPO_OPERATIVO
A2: 821022 | B2: REBOQUE CANAVIEIRO RANDON 4 EIXOS | C2: IMPLEMENTO RODOVIARIO | D2: REBOQUE CANAVIEIRO 4 EIXOS
A3: 811022 | B3: SEMI-REBOQUE CANAVIEIRO RANDON 2 EIXO | C3: IMPLEMENTO RODOVIARIO | D3: SEMI-REBOQUES CANAVIEIROS
A4: 821122 | B4: REBOQUE CANAVIEIRO RANDON 4 EIXOS | C4: IMPLEMENTO RODOVIARIO | D4: REBOQUE CANAVIEIRO 4 EIXOS
A5: 811122 | B5: SEMI-REBOQUE CANAVIEIRO RANDON 2 EIXO | C5: IMPLEMENTO RODOVIARIO | D5: SEMI-REBOQUES CANAVIEIROS
A6: 525 | B6: VOLKSWAGEN 17-180 EURO3 WORKER (ÁGUA) | C6: CAMINHOES | D6: BOMBEIROS
A7: 32217 | B7: VOLVO FM 500 6X4 - PRANCHA | C7: CAMINHOES | D7: PRANCHA
A8: 41102 | B8: VOLKSWAGEN 26-260 OFICINA VOLANTE | C8: CAMINHOES | D8: OFICINA VOLANTE
A9: 31120 | B9: VOLVO FM 540 6X4 - CANAVIEIRO | C9: CAMINHOES | D9: CAVALO MECANICO
A10: 80422 | B10: CASE AUSTOFT 9900 - COLHEDORA | C10: COLHEDORA | D10: COLHEDORA DE CANA PICADA
A11: 80322 | B11: CASE AUSTOFT 9900 - COLHEDORA | C11: COLHEDORA | D11: COLHEDORA DE CANA PICADA
A12: 80122 | B12: CASE AUSTOFT 9900 - COLHEDORA | C12: COLHEDORA | D12: COLHEDORA DE CANA PICADA
A13: 80222 | B13: CASE AUSTOFT 9900 - COLHEDORA | C13: COLHEDORA | D13: COLHEDORA DE CANA PICADA
... A262: 81824 | B262: SEMI-REBOQUE CANAVIEIRO SERGOMEL 2 EIXO | C262: IMPLEMENTO RODOVIARIO | D262: SEMI-REBOQUES CANAVIEIROS
