Workbook
Name a: #REF!
Name Ano_Sel: #REF!
Name Base_Mes: #REF!
Name Base_Safra: #REF!
Name Div_Valor: #REF!
Name Mes_Sel: #REF!
Name Moeda_Sel: #REF!
Name Rel_Recursos: #REF!
Name Tp_Desc_Mes: #REF!
Name Tp_Var: #REF!

Sheet TABELA
L2: Realizado
D3: Cod. Operação | E3: Operação | F3: Modelo | G3: Frota | H3: Turno | I3: Há/h | J3: Horas trabalhado | K3: Há/Dia | L3: Horas trabalhado | M3: Há/Dia | N3: Observação
D4: 1031 | E4: 1ª HERBICIDA | F4: PATRIOT 70122 | G4: 70122 | H4: =_xlfn.XLOOKUP(D4,'Rendimentos '!B:B,'Rendimentos '!D:D) -> 1 | I4: =_xlfn.XLOOKUP(D4,'Rendimentos '!B:B,'Rendimentos '!H:H) -> 17 | J4: =_xlfn.XLOOKUP(D4,'Plano Horas'!C:C,'Plano Horas'!P:P) -> 3.95 | K4: =I4*J4 -> 67.15
D5: 1031 | E5: 1ª HERBICIDA | F5: JONH DEERE 70121 | G5: 70121 | H5: =_xlfn.XLOOKUP(D5,'Rendimentos '!B:B,'Rendimentos '!D:D) -> 1 | I5: =_xlfn.XLOOKUP(D5,'Rendimentos '!B:B,'Rendimentos '!H:H) -> 17 | J5: =_xlfn.XLOOKUP(D5,'Plano Horas'!C:C,'Plano Horas'!P:P) -> 3.95 | K5: =I5*J5 -> 67.15
D6: 1031 | E6: 1ª HERBICIDA | F6: VALTRA BS 340 | G6: 340 | H6: =_xlfn.XLOOKUP(D6,'Rendimentos '!B:B,'Rendimentos '!D:D) -> 1 | I6: =_xlfn.XLOOKUP(D6,'Rendimentos '!B:B,'Rendimentos '!H:H) -> 17 | J6: =_xlfn.XLOOKUP(D6,'Plano Horas'!C:C,'Plano Horas'!P:P) -> 3.95 | K6: =I6*J6 -> 67.15
D7: 1091 | E7: CARREADOR | F7: NEW HOLLAND 11125 | G7: 11125 | H7: =_xlfn.XLOOKUP(D7,'Rendimentos '!B:B,'Rendimentos '!D:D) -> 1 | I7: =_xlfn.XLOOKUP(D7,'Rendimentos '!B:B,'Rendimentos '!H:H) -> 0.5 | J7: =_xlfn.XLOOKUP(D7,'Plano Horas'!C:C,'Plano Horas'!P:P) -> 3.6333333 | K7: =I7*J7 -> 1.8166667
D8: 1031 | E8: 1ª HERBICIDA | F8: NEW HOLLAND 11225 | G8: 11225 | H8: =_xlfn.XLOOKUP(D8,'Rendimentos '!B:B,'Rendimentos '!D:D) -> 1 | I8: =_xlfn.XLOOKUP(D8,'Rendimentos '!B:B,'Rendimentos '!H:H) -> 17 | J8: =_xlfn.XLOOKUP(D8,'Plano Horas'!C:C,'Plano Horas'!P:P) -> 3.95 | K8: =I8*J8 -> 67.15
D9: 1091 | E9: CATAÇÃO | F9: CASE 11124 | G9: 11124 | H9: =_xlfn.XLOOKUP(D9,'Rendimentos '!B:B,'Rendimentos '!D:D) -> 1 | I9: =_xlfn.XLOOKUP(D9,'Rendimentos '!B:B,'Rendimentos '!H:H) -> 0.5 | J9: =_xlfn.XLOOKUP(D9,'Plano Horas'!C:C,'Plano Horas'!P:P) -> 3.6333333 | K9: =I9*J9 -> 1.8166667
D10: 1091 | E10: CATAÇÃO | F10: CASE 11224 | G10: 11224 | H10: =_xlfn.XLOOKUP(D10,'Rendimentos '!B:B,'Rendimentos '!D:D) -> 1 | I10: =_xlfn.XLOOKUP(D10,'Rendimentos '!B:B,'Rendimentos '!H:H) -> 0.5 | J10: =_xlfn.XLOOKUP(D10,'Plano Horas'!C:C,'Plano Horas'!P:P) -> 3.6333333 | K10: =I10*J10 -> 1.8166667
D11: 1073 | E11: CORTE SOQUEIRA | F11: NEW HOLLAND 11418 | G11: 11418 | H11: =_xlfn.XLOOKUP(D11,'Rendimentos '!B:B,'Rendimentos '!D:D) -> 1 | I11: =_xlfn.XLOOKUP(D11,'Rendimentos '!B:B,'Rendimentos '!H:H) -> 1.5 | J11: =_xlfn.XLOOKUP(D11,'Plano Horas'!C:C,'Plano Horas'!P:P) -> 4.0333333 | K11: =I11*J11 -> 6.05
D12: 1073 | E12: CORTE SOQUEIRA | F12: NEW HOLLAND 11518 | G12: 11518 | H12: =_xlfn.XLOOKUP(D12,'Rendimentos '!B:B,'Rendimentos '!D:D) -> 1 | I12: =_xlfn.XLOOKUP(D12,'Rendimentos '!B:B,'Rendimentos '!H:H) -> 1.5 | J12: =_xlfn.XLOOKUP(D12,'Plano Horas'!C:C,'Plano Horas'!P:P) -> 4.0333333 | K12: =I12*J12 -> 6.05
D13: 1073 | E13: CORTE SOQUEIRA | F13: NEW HOLLAND 11618 | G13: 11618 | H13: =_xlfn.XLOOKUP(D13,'Rendimentos '!B:B,'Rendimentos '!D:D) -> 1 | I13: =_xlfn.XLOOKUP(D13,'Rendimentos '!B:B,'Rendimentos '!H:H) -> 1.5 | J13: =_xlfn.XLOOKUP(D13,'Plano Horas'!C:C,'Plano Horas'!P:P) -> 4.0333333 | K13: =I13*J13 -> 6.05
D14: 1073 | E14: CORTE SOQUEIRA | F14: NEW HOLLAND 11718 | G14: 11718 | H14: =_xlfn.XLOOKUP(D14,'Rendimentos '!B:B,'Rendimentos '!D:D) -> 1 | I14: =_xlfn.XLOOKUP(D14,'Rendimentos '!B:B,'Rendimentos '!H:H) -> 1.5 | J14: =_xlfn.XLOOKUP(D14,'Plano Horas'!C:C,'Plano Horas'!P:P) -> 4.0333333 | K14: =I14*J14 -> 6.05
D15: 1020 | E15: QUEBRA LOMBO | F15: PUMA 11324 | G15: 11324 | H15: =_xlfn.XLOOKUP(D15,'Rendimentos '!B:B,'Rendimentos '!D:D) -> 1 | I15: =_xlfn.XLOOKUP(D15,'Rendimentos '!B:B,'Rendimentos '!H:H) -> 1.4 | J15: =_xlfn.XLOOKUP(D15,'Plano Horas'!C:C,'Plano Horas'!P:P) -> 4.1166667 | K15: =I15*J15 -> 5.7633333
... D20: 1091 | E20: CATAÇÃO | F20: HONDA 2320 | G20: 2320 | H20: =_xlfn.XLOOKUP(D20,'Rendimentos '!B:B,'Rendimentos '!D:D) -> 1 | I20: =_xlfn.XLOOKUP(D20,'Rendimentos '!B:B,'Rendimentos '!H:H) -> 0.5 | J20: =_xlfn.XLOOKUP(D20,'Plano Horas'!C:C,'Plano Horas'!P:P) -> 3.6333333 | K20: =I20*J20 -> 1.8166667
D21: 1091 | E21: CATAÇÃO | F21: COSTAL | G21: COSTAL | H21: =_xlfn.XLOOKUP(D21,'Rendimentos '!B:B,'Rendimentos '!D:D) -> 1 | I21: =_xlfn.XLOOKUP(D21,'Rendimentos '!B:B,'Rendimentos '!H:H) -> 0.5 | J21: =_xlfn.XLOOKUP(D21,'Plano Horas'!C:C,'Plano Horas'!P:P) -> 3.6333333 | K21: =I21*J21 -> 1.8166667

Sheet Plano Horas
B2: Operação | C2: CD_Operação | D2: DE_Operação | E2: Turnos | F2: Horas de atividade dia | G2: Disp. Mecânica | H2: Deslocamento | I2: Troca de Turno | J2: Check-list | K2: Abast.e/ou lubrificação | L2: Refeição | M2: Mudança de área | N2: Manobra | O2: Abast. Insumo | P2: Total horas disponivel dia para produção
E3: qtd. | F3: h | G3: % | H3: h/dia | I3: h/dia | J3: h/dia | K3: h/dia | L3: h/dia | M3: h/dia | N3: % | O3: h/dia | P3: h
F4: 0.33333333 | H4: 0.0625 | J4: 0.0069444444 | K4: 0.0069444444 | L4: 0.041666667 | M4: 0.020833333 | N4: 0 | O4: 0
B5: PREPARO DE SOLO | C5: 1001 | D5: TERRACEAMENTO | E5: 1 | F5: =IF($E5=1,$F$4,IF($E5=2,$F$4*2,($F$4*3)-0.0001)) -> 0.33333333 | G5: 0.9 | H5: 0.027777778 | J5: =E5*$J$4 -> 0.0069444444 | K5: 0.013888889 | L5: =$L$4*$E5 -> 0.041666667 | M5: 0.03125 | N5: 0 | O5: 0 | P5: =((F5*24)*G5)-(SUM(H5:O5)*24) -> 4.2833333
C6: 1004 | D6: CURVA EM NÍVEL | E6: 1 | F6: =IF($E6=1,$F$4,IF($E6=2,$F$4*2,($F$4*3)-0.0001)) -> 0.33333333 | G6: 0.9 | H6: 0.027777778 | J6: =E6*$J$4 -> 0.0069444444 | K6: 0.013888889 | L6: =$L$4*$E6 -> 0.041666667 | M6: 0.03125 | N6: 0 | O6: 0 | P6: =((F6*24)*G6)-(SUM(H6:O6)*24) -> 4.2833333
C7: 1005 | D7: SISTEMATIZAÇÃO | E7: 1 | F7: =IF($E7=1,$F$4,IF($E7=2,$F$4*2,($F$4*3)-0.0001)) -> 0.33333333 | G7: 0.9 | H7: 0.027777778 | J7: =E7*$J$4 -> 0.0069444444 | K7: 0.013888889 | L7: =$L$4*$E7 -> 0.041666667 | M7: 0.03125 | N7: 0 | O7: 0 | P7: =((F7*24)*G7)-(SUM(H7:O7)*24) -> 4.2833333
C8: 1011 | D8: ARAÇÃO | E8: 1 | F8: =IF($E8=1,$F$4,IF($E8=2,$F$4*2,($F$4*3)-0.0001)) -> 0.33333333 | G8: 0.9 | H8: 0.027777778 | J8: =E8*$J$4 -> 0.0069444444 | K8: 0.013888889 | L8: =$L$4*$E8 -> 0.041666667 | M8: 0.03125 | N8: 0 | O8: 0 | P8: =((F8*24)*G8)-(SUM(H8:O8)*24) -> 4.2833333
C9: 1013 | D9: GRADAGEM ARADORA | E9: 1 | F9: =IF($E9=1,$F$4,IF($E9=2,$F$4*2,($F$4*3)-0.0001)) -> 0.33333333 | G9: 0.85 | H9: 0.027777778 | J9: =E9*$J$4 -> 0.0069444444 | K9: 0.013888889 | L9: =$L$4*$E9 -> 0.041666667 | M9: 0.03125 | N9: 0 | O9: 0 | P9: =((F9*24)*G9)-(SUM(H9:O9)*24) -> 3.8833333
C10: 1014 | D10: GRADAGEM INTERMEDIÁRIA | E10: 1 | F10: =IF($E10=1,$F$4,IF($E10=2,$F$4*2,($F$4*3)-0.0001)) -> 0.33333333 | G10: 0.85 | H10: 0.027777778 | J10: =E10*$J$4 -> 0.0069444444 | K10: 0.013888889 | L10: =$L$4*$E10 -> 0.041666667 | M10: 0.03125 | N10: 0 | O10: 0 | P10: =((F10*24)*G10)-(SUM(H10:O10)*24) -> 3.8833333
C11: 1015 | D11: GRADAGEM NIVELADORA | E11: 1 | F11: =IF($E11=1,$F$4,IF($E11=2,$F$4*2,($F$4*3)-0.0001)) -> 0.33333333 | G11: 0.85 | H11: 0.027777778 | J11: =E11*$J$4 -> 0.0069444444 | K11: 0.013888889 | L11: =$L$4*$E11 -> 0.041666667 | M11: 0.03125 | N11: 0 | O11: 0 | P11: =((F11*24)*G11)-(SUM(H11:O11)*24) -> 3.8833333
C12: 1016 | D12: SUBSOLAGEM | E12: 1 | F12: =IF($E12=1,$F$4,IF($E12=2,$F$4*2,($F$4*3)-0.0001)) -> 0.33333333 | G12: 0.85 | H12: 0.027777778 | J12: =E12*$J$4 -> 0.0069444444 | K12: 0.013888889 | L12: =$L$4*$E12 -> 0.041666667 | M12: 0.03125 | N12: 0 | O12: 0 | P12: =((F12*24)*G12)-(SUM(H12:O12)*24) -> 3.8833333
C13: 1024 | D13: ENLEIRAMENTO DE PALHA | E13: 1 | F13: =IF($E13=1,$F$4,IF($E13=2,$F$4*2,($F$4*3)-0.0001)) -> 0.33333333 | G13: 0.85 | H13: 0.027777778 | J13: =E13*$J$4 -> 0.0069444444 | K13: 0.013888889 | L13: =$L$4*$E13 -> 0.041666667 | M13: 0.03125 | N13: 0 | O13: 0 | P13: =((F13*24)*G13)-(SUM(H13:O13)*24) -> 3.8833333
C14: 1026 | D14: APLICAÇÃO DE FOSFATO | E14: 1 | F14: =IF($E14=1,$F$4,IF($E14=2,$F$4*2,($F$4*3)-0.0001)) -> 0.33333333 | G14: 0.85 | H14: 0.027777778 | J14: =E14*$J$4 -> 0.0069444444 | K14: 0.013888889 | L14: =$L$4*$E14 -> 0.041666667 | M14: 0.03125 | N14: 0 | O14: 0.0069444444 | P14: =((F14*24)*G14)-(SUM(H14:O14)*24) -> 3.7166667
C15: 1028 | D15: APLICAÇÃO DE CALCÁRIO | E15: 1 | F15: =IF($E15=1,$F$4,IF($E15=2,$F$4*2,($F$4*3)-0.0001)) -> 0.33333333 | G15: 0.85 | H15: 0.027777778 | J15: =E15*$J$4 -> 0.0069444444 | K15: 0.013888889 | L15: =$L$4*$E15 -> 0.041666667 | M15: 0.03125 | N15: 0 | O15: 0.0069444444 | P15: =((F15*24)*G15)-(SUM(H15:O15)*24) -> 3.7166667
C16: 1029 | D16: APLICAÇÃO DE GESSO | E16: 1 | F16: =IF($E16=1,$F$4,IF($E16=2,$F$4*2,($F$4*3)-0.0001)) -> 0.33333333 | G16: 0.85 | H16: 0.027777778 | J16: =E16*$J$4 -> 0.0069444444 | K16: 0.013888889 | L16: =$L$4*$E16 -> 0.041666667 | M16: 0.03125 | N16: 0 | O16: 0.0069444444 | P16: =((F16*24)*G16)-(SUM(H16:O16)*24) -> 3.7166667
C17: 1033 | D17: APLICAÇÃO DE TORTA DE FILTRO | E17: 1 | F17: =IF($E17=1,$F$4,IF($E17=2,$F$4*2,($F$4*3)-0.0001)) -> 0.33333333 | G17: 0.85 | H17: 0.027777778 | J17: =E17*$J$4 -> 0.0069444444 | K17: 0.013888889 | L17: =$L$4*$E17 -> 0.041666667 | M17: 0.03125 | N17: 0 | O17: 0.0069444444 | P17: =((F17*24)*G17)-(SUM(H17:O17)*24) -> 3.7166667
... C19: 1061 | D19: ENFARDAMENTO DE PALHA | E19: 1 | F19: =IF($E19=1,$F$4,IF($E19=2,$F$4*2,($F$4*3)-0.0001)) -> 0.33333333 | G19: 0.85 | H19: 0.027777778 | J19: =E19*$J$4 -> 0.0069444444 | K19: 0.013888889 | L19: =$L$4*$E19 -> 0.041666667 | M19: 0.03125 | N19: 0 | O19: 0 | P19: =((F19*24)*G19)-(SUM(H19:O19)*24) -> 3.8833333
B20: TRATOS CULTURAIS | C20: 1020 | D20: QUEBRA DE LOMBO | E20: 1 | F20: =IF($E20=1,$F$4,IF($E20=2,$F$4*2,($F$4*3)-0.0001)) -> 0.33333333 | G20: 0.9 | H20: 0.027777778 | J20: =E20*$J$4 -> 0.0069444444 | K20: 0.013888889 | L20: =$L$4*$E20 -> 0.041666667 | M20: 0.03125 | N20: 0 | O20: 0.0069444444 | P20: =((F20*24)*G20)-(SUM(H20:O20)*24) -> 4.1166667
C21: 1022 | D21: CULTIVO (adubação soca) | E21: 1 | F21: =IF($E21=1,$F$4,IF($E21=2,$F$4*2,($F$4*3)-0.0001)) -> 0.33333333 | G21: 0.9 | H21: 0.027777778 | J21: =E21*$J$4 -> 0.0069444444 | K21: 0.013888889 | L21: =$L$4*$E21 -> 0.041666667 | M21: 0.03125 | N21: 0 | O21: 0.010416667 | P21: =((F21*24)*G21)-(SUM(H21:O21)*24) -> 4.0333333
C22: 1031 | D22: APLICAÇÃO DE HERBICIDA | E22: 1 | F22: =IF($E22=1,$F$4,IF($E22=2,$F$4*2,($F$4*3)-0.0001)) -> 0.33333333 | G22: 0.9 | H22: 0.027777778 | J22: =E22*$J$4 -> 0.0069444444 | K22: 0.013888889 | L22: =$L$4*$E22 -> 0.041666667 | M22: 0.03125 | N22: 0 | O22: 0.013888889 | P22: =((F22*24)*G22)-(SUM(H22:O22)*24) -> 3.95
C23: 1032 | D23: APLICAÇÃO DE INSETICIDA | E23: 1 | F23: =IF($E23=1,$F$4,IF($E23=2,$F$4*2,($F$4*3)-0.0001)) -> 0.33333333 | G23: 0.9 | H23: 0.027777778 | J23: =E23*$J$4 -> 0.0069444444 | K23: 0.013888889 | L23: =$L$4*$E23 -> 0.041666667 | M23: 0.03125 | N23: 0 | O23: 0.010416667 | P23: =((F23*24)*G23)-(SUM(H23:O23)*24) -> 4.0333333
C24: 1073 | D24: Apl Inseticida Em Profundidade | E24: 1 | F24: =IF($E24=1,$F$4,IF($E24=2,$F$4*2,($F$4*3)-0.0001)) -> 0.33333333 | G24: 0.9 | H24: 0.027777778 | J24: =E24*$J$4 -> 0.0069444444 | K24: 0.013888889 | L24: =$L$4*$E24 -> 0.041666667 | M24: 0.03125 | N24: 0 | O24: 0.010416667 | P24: =((F24*24)*G24)-(SUM(H24:O24)*24) -> 4.0333333
C25: 1035 | D25: APLIC DE VINHAÇA VIA CAMINHÃO | E25: 1 | F25: =IF($E25=1,$F$4,IF($E25=2,$F$4*2,($F$4*3)-0.0001)) -> 0.33333333 | G25: 0.9 | H25: 0 | J25: =E25*$J$4 -> 0.0069444444 | K25: 0.013888889 | L25: =$L$4*$E25 -> 0.041666667 | M25: 0.03125 | N25: 0 | O25: 0 | P25: =((F25*24)*G25)-(SUM(H25:O25)*24) -> 4.95
C26: 1050 | D26: TRAÇÃO MOTOBOMBA (canal) | E26: 1 | F26: =IF($E26=1,$F$4,IF($E26=2,$F$4*2,($F$4*3)-0.0001)) -> 0.33333333 | G26: 0.9 | H26: 0 | J26: =E26*$J$4 -> 0.0069444444 | K26: 0.013888889 | L26: =$L$4*$E26 -> 0.041666667 | M26: 0.03125 | N26: 0 | O26: 0 | P26: =((F26*24)*G26)-(SUM(H26:O26)*24) -> 4.95
C27: 1078 | E27: 1 | F27: =IF($E27=1,$F$4,IF($E27=2,$F$4*2,($F$4*3)-0.0001)) -> 0.33333333 | G27: 0.8 | H27: 0.027777778 | J27: =E27*$J$4 -> 0.0069444444 | K27: 0.013888889 | L27: =$L$4*$E27 -> 0.041666667 | M27: 0.03125 | N27: 0 | O27: 0.010416667 | P27: =((F27*24)*G27)-(SUM(H27:O27)*24) -> 3.2333333
C28: 1071 | E28: 1 | F28: =IF($E28=1,$F$4,IF($E28=2,$F$4*2,($F$4*3)-0.0001)) -> 0.33333333 | G28: 0.85 | H28: 0.027777778 | J28: =E28*$J$4 -> 0.0069444444 | K28: 0.013888889 | L28: =$L$4*$E28 -> 0.041666667 | M28: 0.03125 | N28: 0 | O28: 0.010416667 | P28: =((F28*24)*G28)-(SUM(H28:O28)*24) -> 3.6333333
C29: 1090 | E29: 1 | F29: =IF($E29=1,$F$4,IF($E29=2,$F$4*2,($F$4*3)-0.0001)) -> 0.33333333 | G29: 0.85 | H29: 0.027777778 | J29: =E29*$J$4 -> 0.0069444444 | K29: 0.013888889 | L29: =$L$4*$E29 -> 0.041666667 | M29: 0.03125 | N29: 0 | O29: 0.010416667 | P29: =((F29*24)*G29)-(SUM(H29:O29)*24) -> 3.6333333
C30: 1091 | E30: 1 | F30: =IF($E30=1,$F$4,IF($E30=2,$F$4*2,($F$4*3)-0.0001)) -> 0.33333333 | G30: 0.85 | H30: 0.027777778 | J30: =E30*$J$4 -> 0.0069444444 | K30: 0.013888889 | L30: =$L$4*$E30 -> 0.041666667 | M30: 0.03125 | N30: 0 | O30: 0.010416667 | P30: =((F30*24)*G30)-(SUM(H30:O30)*24) -> 3.6333333
B31: PLANTIO | C31: 1.01 | D31: Plantio (Meiose) | E31: 1 | F31: =IF($E31=1,$F$4,IF($E31=2,$F$4*2,($F$4*3)-0.0001)) -> 0.33333333 | P31: =((F31*24)*G31)-(SUM(H31:O31)*24) -> 0
C32: 1.02 | D32: Plantio (Cantose) | E32: 1 | F32: =IF($E32=1,$F$4,IF($E32=2,$F$4*2,($F$4*3)-0.0001)) -> 0.33333333 | P32: =((F32*24)*G32)-(SUM(H32:O32)*24) -> 0
C33: 1.03 | D33: Plantio (Convencional) | E33: 1 | F33: =IF($E33=1,$F$4,IF($E33=2,$F$4*2,($F$4*3)-0.0001)) -> 0.33333333 | G33: 0.85 | H33: 0.027777778 | L33: 0.041666667 | P33: =((F33*24)*G33)-(SUM(H33:O33)*24) -> 5.1333333
C34: 1.04 | D34: Plantio (MPB) | E34: 1 | F34: =IF($E34=1,$F$4,IF($E34=2,$F$4*2,($F$4*3)-0.0001)) -> 0.33333333 | P34: =((F34*24)*G34)-(SUM(H34:O34)*24) -> 0
D35: Corte de Muda (16 ton. p/ há) | E35: 1 | F35: =IF($E35=1,$F$4,IF($E35=2,$F$4*2,($F$4*3)-0.0001)) -> 0.33333333 | P35: =((F35*24)*G35)-(SUM(H35:O35)*24) -> 0
C36: 1018 | D36: SULCAÇÃO | E36: 1 | F36: =IF($E36=1,$F$4,IF($E36=2,$F$4*2,($F$4*3)-0.0001)) -> 0.33333333 | G36: 0.85 | H36: 0.027777778 | J36: 0.013888889 | K36: 0.013888889 | L36: 0.083333333 | M36: 0.03125 | N36: 0 | O36: 0.0069444444 | P36: =((F36*24)*G36)-(SUM(H36:O36)*24) -> 2.55
C37: 4001 | D37: Colheita | E37: 1 | F37: =IF($E37=1,$F$4,IF($E37=2,$F$4*2,($F$4*3)-0.0001)) -> 0.33333333 | G37: 0.85 | H37: 0 | I37: 0.020833333 | J37: 0.020833333 | K37: 0.033333333 | L37: 0.0625 | M37: 0.025 | N37: 0.06875 | O37: 0.041666667 | P37: =((F37*24)*G37)-(SUM(H37:O37)*24) -> 0.25
C38: xx1 | D38: Biomassa | E38: 1 | F38: =IF($E38=1,$F$4,IF($E38=2,$F$4*2,($F$4*3)-0.0001)) -> 0.33333333 | G38: 0.85 | H38: 0.027777778 | J38: 0.0069444444 | K38: 0.013888889 | L38: 0.041666667 | M38: 0.03125 | N38: 0 | O38: 0 | P38: =((F38*24)*G38)-(SUM(H38:O38)*24) -> 3.8833333
C39: 1096 | E39: 1 | F39: =IF($E39=1,$F$4,IF($E39=2,$F$4*2,($F$4*3)-0.0001)) -> 0.33333333 | G39: 0.9 | H39: 0.027777778 | J39: =E39*$J$4 -> 0.0069444444 | K39: 0.013888889 | L39: =$L$4*$E39 -> 0.041666667 | M39: 0.03125 | N39: 0 | O39: 0 | P39: =((F39*24)*G39)-(SUM(H39:O39)*24) -> 4.2833333
C40: 1002 | E40: 1 | F40: =IF($E40=1,$F$4,IF($E40=2,$F$4*2,($F$4*3)-0.0001)) -> 0.33333333 | G40: 0.9 | H40: 0.027777778 | J40: =E40*$J$4 -> 0.0069444444 | K40: 0.013888889 | L40: =$L$4*$E40 -> 0.041666667 | M40: 0.03125 | N40: 0 | O40: 0 | P40: =((F40*24)*G40)-(SUM(H40:O40)*24) -> 4.2833333
C41: 1003 | E41: 1 | F41: =IF($E41=1,$F$4,IF($E41=2,$F$4*2,($F$4*3)-0.0001)) -> 0.33333333 | G41: 0.9 | H41: 0.027777778 | J41: =E41*$J$4 -> 0.0069444444 | K41: 0.013888889 | L41: =$L$4*$E41 -> 0.041666667 | M41: 0.03125 | N41: 0 | O41: 0 | P41: =((F41*24)*G41)-(SUM(H41:O41)*24) -> 4.2833333
C42: 1019 | E42: 1 | F42: =IF($E42=1,$F$4,IF($E42=2,$F$4*2,($F$4*3)-0.0001)) -> 0.33333333 | G42: 0.9 | H42: 0.027777778 | J42: =E42*$J$4 -> 0.0069444444 | K42: 0.013888889 | L42: =$L$4*$E42 -> 0.041666667 | M42: 0.03125 | N42: 0 | O42: 0 | P42: =((F42*24)*G42)-(SUM(H42:O42)*24) -> 4.2833333
...

Sheet Rendimentos 
B1: Cód. Operação | C1: Descr. Operação | D1: Turno | E1: Tipo Trator | F1: U/M | G1: Rendimento | H1: Rendimento Validado | I1: Check | S1: Operação Agrícola | T1: Descrição | U1: Total
B2: 1001 | C2: Terraceamento | D2: 1 | E2: Pesado | F2: há/h | G2: 2.4 | H2: 2.4 | I2: =VLOOKUP(B2,S:U,3,0) -> 1 | S2: 13 | T2: CORTE MANUAL DE CANA QUEIMADA | U2: 1
B3: 1004 | C3: Curva Em Nível | D3: 1 | E3: Pesado | F3: há/h | G3: 1.7 | H3: 3 | I3: =VLOOKUP(B3,S:U,3,0) -> 2 | S3: 15 | T3: DISTRIBUIÇÃO DE CANA/SULCO | U3: 1
B4: 1005 | C4: Sistematização | D4: 1 | E4: Pesado | F4: há/h | G4: 3.3 | H4: 3.3 | I4: =VLOOKUP(B4,S:U,3,0) -> 1 | S4: 22 | T4: SERVICOS DIVERSOS | U4: 1
B5: 1011 | C5: Aração | D5: 1 | E5: Médio | F5: há/h | G5: 1.1 | H5: 0.5 | I5: =VLOOKUP(B5,S:U,3,0) -> 0.59375 | M5: 5424 | S5: 29 | T5: REPLANTIO MANUAL DE CANA | U5: 1
B6: 1013 | C6: Gradagem Aradora | D6: 1 | E6: Pesado | F6: há/h | G6: 1.4 | H6: 1.1 | I6: =VLOOKUP(B6,S:U,3,0) -> 1.1 | M6: 5395 | S6: 1001 | T6: TERRACEAMENTO | U6: 1
B7: 1014 | C7: Gradagem Intermediária | D7: 1 | E7: Médio/Pesado | F7: há/h | G7: 1.5 | H7: 1.5 | I7: =VLOOKUP(B7,S:U,3,0) -> 1.5 | M7: 5335 | S7: 1002 | T7: TERRAPLANAGEM | U7: 1.2571429
B8: 1015 | C8: Gradagem Niveladora | D8: 1 | E8: Médio/Pesado | F8: há/h | G8: 2.2 | H8: 2.2 | I8: =VLOOKUP(B8,S:U,3,0) -> 1.9675676 | S8: 1003 | T8: CONSERVAÇÃO DE ESTRADAS | U8: 1.2142857
B9: 1016 | C9: Subsolagem | D9: 1 | E9: Pesado | F9: há/h | G9: 1.5 | H9: 0.9 | I9: =VLOOKUP(B9,S:U,3,0) -> 0.90322581 | S9: 1004 | T9: CURVA EM NÍVEL | U9: 2
B10: 1018 | C10: Sulcação | D10: 1 | E10: Médio | F10: há/h | G10: 2 | H10: 1.2 | I10: =VLOOKUP(B10,S:U,3,0) -> 1.1333333 | S10: 1005 | T10: SISTEMATIZAÇÃO | U10: 1
B11: 1020 | C11: Quebra De Lombo | D11: 1 | E11: Médio | F11: há/h | G11: 1.4 | H11: 1.4 | I11: =VLOOKUP(B11,S:U,3,0) -> 1 | S11: 1006 | T11: ARRANQUIO DE CITRUS | U11: 1
B12: 1022 | C12: Cultivo | D12: 1 | E12: Medio | F12: há/h | G12: 1.5 | H12: 1.5 | I12: =VLOOKUP(B12,S:U,3,0) -> 1 | S12: 1007 | T12: ARRANQUIO DE CITRUS DENSIDADE | U12: 1
B13: 1024 | C13: Enleiramento De Palha | D13: 1 | E13: Leve | F13: há/h | G13: 5.2 | H13: 5.2 | I13: =VLOOKUP(B13,S:U,3,0) -> 4.5777778 | S13: 1008 | T13: ARRANQUIO DE CITRUS CLEÓPATRA | U13: 1
B14: 1026 | C14: Aplicação De Fosfato | D14: 1 | E14: Leve | F14: há/h | G14: 3.3 | H14: 4 | I14: =VLOOKUP(B14,S:U,3,0) -> 4 | S14: 1009 | T14: ARRANQUIO DE CITRUMELO | U14: 1
B15: 1028 | C15: Aplicação De Calcário | D15: 1 | E15: Leve | F15: há/h | G15: 3.9 | H15: 4 | I15: =VLOOKUP(B15,S:U,3,0) -> 3.5555556 | S15: 1010 | T15: QUEIMA DE CITRUS | U15: 1
B16: 1029 | C16: Aplicação De Gesso | D16: 1 | E16: Leve | F16: há/h | G16: 4.6 | H16: 4 | I16: =VLOOKUP(B16,S:U,3,0) -> 3.9090909 | S16: 1011 | T16: ARAÇÃO | U16: 0.59375
B17: 1031 | C17: 1ª Aplicação De Herbicida | D17: 1 | E17: Leve | F17: há/h | G17: 4.6 | H17: 17 | I17: =VLOOKUP(B17,S:U,3,0) -> 20.642857 | S17: 1012 | T17: ARAÇÃO COM DEFENSIVOS | U17: 1
B18: 1073 | C18: Apl Inseticida Em Profundidade | D18: 1 | E18: Leve | F18: há/h | G18: 8.6 | H18: 1.5 | I18: =VLOOKUP(B18,S:U,3,0) -> 1.1666667 | S18: 1013 | T18: GRADAGEM ARADORA | U18: 1.1
B19: 1032 | C19: Aplicação De Inseticida | D19: 1 | E19: Leve | F19: há/h | G19: 8.6 | H19: 15 | I19: =VLOOKUP(B19,S:U,3,0) -> 22.025217 | S19: 1014 | T19: GRADAGEM INTERMEDIÁRIA | U19: 1.5
... B25: 1071 | C25: Aplicação Mista Correção Solo | D25: 1 | E25: Leve | F25: há/h | G25: 4.6 | H25: 4 | I25: =VLOOKUP(B25,S:U,3,0) -> 4 | S25: 1020 | T25: QUEBRA DE LOMBO | U25: 1
B26: 1078 | C26: 2ª Aplicação De Herbicida | D26: 1 | E26: Leve | F26: há/h | H26: 19 | I26: =VLOOKUP(B26,S:U,3,0) -> 18.6 | S26: 1022 | T26: CULTIVO | U26: 1
B27: 1090 | C27: Repasse Aplicação Herbicida | D27: 1 | E27: Leve | F27: há/h | H27: 5 | I27: =VLOOKUP(B27,S:U,3,0) -> 5.375 | S27: 1023 | T27: COBRIÇÃO DE CANA | U27: 1
B28: 1091 | C28: Aplic. Herb Man - Cat. Quimíca | D28: 1 | E28: Leve | F28: há/h | H28: 0.5 | I28: =VLOOKUP(B28,S:U,3,0) -> 2.2 | S28: 1024 | T28: ENLEIRAMENTO DE PALHA | U28: 4.5777778
B29: 1.01 | C29: Plantio (Meiose) | D29: 1 | E29: Manual | F29: há/h | G29: 0 | H29: 0.2 | I29: =VLOOKUP(B29,S:U,3,0) -> #N/A | S29: 1025 | T29: ARRANQUIO DE TOCO / DIVERSOS | U29: 1
B30: 1.02 | C30: Plantio (Cantose) | D30: 1 | E30: Manual | F30: há/h | G30: 0 | H30: 0.4 | I30: =VLOOKUP(B30,S:U,3,0) -> #N/A | S30: 1026 | T30: APLICAÇÃO DE FOSFATO | U30: 4
B31: 1.03 | C31: Plantio (Convencional) - Equipe | D31: 1 | E31: Manual | F31: há/dia | G31: 0 | H31: 15 | I31: =VLOOKUP(B31,S:U,3,0) -> #N/A | S31: 1027 | T31: ADUBAÇÃO AÉREA | U31: 1
B32: 1.04 | C32: Plantio (MPB) | D32: 1 | E32: Manual | F32: há/h | G32: 0 | H32: 0.1 | I32: =VLOOKUP(B32,S:U,3,0) -> #N/A | S32: 1028 | T32: APLICAÇÃO DE CALCÁRIO | U32: 3.5555556
B33: 1.05 | C33: Corte de Muda | D33: 1 | E33: Manual | F33: ton./dia | H33: 6 | I33: =VLOOKUP(B33,S:U,3,0) -> #N/A | S33: 1029 | T33: APLICAÇÃO DE GESSO | U33: 3.9090909
B34: 1096 | C34: Pré Plantio Incorporado (Ppi) | D34: 1 | E34: Leve | F34: há/h | H34: 20.5 | I34: =VLOOKUP(B34,S:U,3,0) -> 20.5 | S34: 1030 | T34: APLICAÇÃO FERTILIZANTE FOLIAR | U34: 1
B35: 1002 | C35: Terraplanagem | D35: 1 | E35: Leve | F35: há/h | H35: 1.2571429 | I35: =VLOOKUP(B35,S:U,3,0) -> 1.2571429 | S35: 1031 | T35: 1ª APLICAÇÃO DE HERBICIDA | U35: 20.642857
B36: 1003 | C36: Conservação De Estradas | D36: 1 | E36: Leve | F36: há/h | H36: 1.2142857 | I36: =VLOOKUP(B36,S:U,3,0) -> 1.2142857 | S36: 1032 | T36: APLICAÇÃO DE INSETICIDA | U36: 22.025217
B37: 1019 | C37: Destruição De Soqueira / Sph | D37: 1 | E37: Leve | F37: há/h | H37: 1 | I37: =VLOOKUP(B37,S:U,3,0) -> 1 | S37: 1033 | T37: APLICAÇÃO DE TORTA DE FILTRO | U37: 0.81
B38: 1081 | C38: Canterizador De Cana | D38: 1 | E38: Leve | F38: há/h | H38: 1 | I38: =VLOOKUP(B38,S:U,3,0) -> 1 | S38: 1034 | T38: APLICAÇÃO DE COMPOSTAGEM | U38: 1
B39: 1106 | C39: Enxada Rotativa | D39: 1 | E39: Leve | F39: há/h | I39: =VLOOKUP(B39,S:U,3,0) -> #N/A | S39: 1035 | T39: APLIC DE VINHAÇA VIA CAMINHÃO | U39: 0.92
B40: 1079 | C40: Aplicação Dessecação | D40: 1 | E40: Leve | F40: há/h | G40: 4.6 | H40: 20 | I40: =VLOOKUP(B40,S:U,3,0) -> 20.555556 | S40: 1036 | T40: APLICAÇÃO DE VINHAÇA VIA CANAL | U40: 0.50434783
S41: 1037 | T41: ABERTURA DE VALETA / CANAL | U41: 1
S42: 1038 | T42: MANUTENÇÃO REDE DE VINHAÇA | U42: 1
S43: 1039 | T43: COMPOSTAGEM | U43: 1
S44: 1040 | T44: LENHEIRO | U44: 1
S45: 1041 | T45: ROÇADEIRA | U45: 1
...
